Workbook

Sheet Summary
B2: Dự án An Bình
B3: Prepared by
B4: Vị trí: | D4: [Cập nhật vị trí dự án An Bình]
B5: Đơn vị tư vấn: | D5: Tiger capital
B6: Tọa độ:
B7: A | C7: Thông số quy hoạch
C9: STT | D9: Hạng mục đất | E9: Diện tích (m2) | F9: Tỷ lệ đất (%) | G9: Hệ số | H9: MĐXD (%) | I9: Tầng cao | J9: Tổng diện tích sàn xây dựng (m2) | K9: Tổng diện tích thương phẩm (m2) | L9: Số lượng sản phẩm | M9: Diện tích trung bình 1 sản phẩm (m2) | N9: Dân số
C10: I | D10: Đất khu vực lập quy hoạch | E10: =+E11+E19+E20+E21 -> 26556 | F10: =+E10/$E$23 -> 0.94081949
C11: 1 | D11: =+'1. thong tin quy hoach'!C10 -> Đất ở | E11: =+'1. thong tin quy hoach'!D10 -> 21178.41 | F11: =+E11/$E$23 -> 0.75030355 | G11: 10.21 | J11: =+J12+J17 -> 172561.1 | K11: =+K12+K17 -> 97820.305 | L11: =+L12+L17 -> 1521.3544 | N11: =+N12+N17 -> 2700
C12: 1.1 | D12: Khối cao tầng | E12: =+'1. thong tin quy hoach'!D12 -> 14605.8 | F12: =+E12/$E$23 -> 0.51745072 | G12: 10.21 | H12: 0.4 | I12: =+'1. thong tin quy hoach'!G12 -> 30 | J12: =+'1. thong tin quy hoach'!I12 -> 146585.35 | K12: =SUM(K13:K16) -> 91247.695 | L12: =SUM(L13:L16) -> 1448.3254 | N12: =+'1. thong tin quy hoach'!M12 -> 2407.884
D13: =+'1. thong tin quy hoach'!C13 -> Căn hộ khối tháp | J13: =+'1. thong tin quy hoach'!I13 -> 103768.6 | K13: =+'1. thong tin quy hoach'!K13 -> 81145.098 | L13: =+'1. thong tin quy hoach'!L13 -> 1275 | M13: =+'1. thong tin quy hoach'!N13 -> 63.643214
D14: =+'1. thong tin quy hoach'!C14 -> Căn shop TM khối đế | J14: =+'1. thong tin quy hoach'!I14 -> 2321.0467 | K14: =+'1. thong tin quy hoach'!K14 -> 2246.1743 | L14: =+'1. thong tin quy hoach'!L14 -> 18 | M14: =+'1. thong tin quy hoach'!N14 -> 124.78746
D15: OFT | J15: =+'1. thong tin quy hoach'!I15 -> 8219.248 | K15: =+'1. thong tin quy hoach'!K15 -> 6156.4232 | L15: =+'1. thong tin quy hoach'!L15 -> 154.32543 | M15: =+'1. thong tin quy hoach'!N15 -> 39.892473
D16: =+'1. thong tin quy hoach'!C16 -> Nhà trẻ | J16: =+'1. thong tin quy hoach'!I16 -> 2000 | K16: =+'1. thong tin quy hoach'!K16 -> 1700 | L16: =+'1. thong tin quy hoach'!L16 -> 1
C17: 1.2 | D17: Khối thấp tầng | E17: =+'1. thong tin quy hoach'!D37 -> 6572.61 | F17: =+E17/$E$23 -> 0.23285282 | G17: 0 | H17: =+'1. thong tin quy hoach'!F37 -> 0.75 | I17: =+'1. thong tin quy hoach'!G37 -> 3 | J17: =+'1. thong tin quy hoach'!I37 -> 25975.746 | K17: =SUM(K18:K18) -> 6572.61 | L17: =+SUM(L18:L18) -> 73.029 | M17: =+M18 -> 90 | N17: =+N18 -> 292.116
D18: ='1. thong tin quy hoach'!C38 -> Nhà ở liên kế khu A | E18: =+'1. thong tin quy hoach'!D38 -> 6572.61 | H18: =+'1. thong tin quy hoach'!F38 -> 0.75 | I18: =+'1. thong tin quy hoach'!G38 -> 3 | J18: =+'1. thong tin quy hoach'!I38 -> 25975.746 | K18: =+'1. thong tin quy hoach'!J38 -> 6572.61 | L18: =+'1. thong tin quy hoach'!L38 -> 73.029 | M18: =+'1. thong tin quy hoach'!N38 -> 90 | N18: =+'1. thong tin quy hoach'!M37 -> 292.116
C19: 2 | D19: Đất công trình công cộng | E19: =+'1. thong tin quy hoach'!D43 -> 0
C20: 3 | D20: Đất cây xanh nhóm ở thấp tầng | E20: =+'1. thong tin quy hoach'!D47 -> 0
C21: 4 | D21: Đất giao thông | E21: =+'1. thong tin quy hoach'!D48 -> 5377.59
C22: II | D22: Đất ngoài khu vực quy hoạch | E22: =+'1. thong tin quy hoach'!D53 -> 1670.456
C23: III | D23: Tổng diện tích đất | E23: =+E10+E22 -> 28226.456
B25: B. | C25: TỔNG MỨC ĐẦU TƯ
C27: Thời điểm triển khai xây dựng (dự kiến): | E27: Q1/2027
C29: STT | D29: Hạng mục | E29: Diện tích (m2) | F29: Đơn giá gồm VAT (trđ/m2) | G29: Giá trị (gồm VAT) (triệu đồng) | I29: Tỷ trọng (%) | L29: Hạng mục | N29: Tổng cộng | O29: 2026 | P29: 2027 | Q29: 2028 | R29: 2029 | S29: 2030 | T29: 2031
C30: I | D30: Các loại chi phí đất & pháp lý | E30: =+E23 -> 28226.456 | F30: =+G30/E30 -> 38.616497 | G30: =SUM(G31:H33) -> 1090006.8 | I30: =+G30/$G$45 -> 0.30237882 | L30: Chi phí đất | N30: =SUM(O30:T30) -> 0
D31: Chi phí nhận chuyển nhượng | E31: =+E30 -> 28226.456 | F31: =+G31/E31 -> 18.422433 | G31: =+'3.Du toan'!F12 -> 520000 | L31: Chi phí chuyển nhượng | N31: =SUM(O31:T31) -> 1 | O31: =SUMIF('2.Tien do'!$E$7:$AN$7,Summary!O$29,'2.Tien do'!$E10:$AN10) -> 1 | P31: =SUMIF('2.Tien do'!$E$7:$AN$7,Summary!P$29,'2.Tien do'!$E10:$AN10) -> 0 | Q31: =SUMIF('2.Tien do'!$E$7:$AN$7,Summary!Q$29,'2.Tien do'!$E10:$AN10) -> 0 | R31: =SUMIF('2.Tien do'!$E$7:$AN$7,Summary!R$29,'2.Tien do'!$E10:$AN10) -> 0 | S31: =SUMIF('2.Tien do'!$E$7:$AN$7,Summary!S$29,'2.Tien do'!$E10:$AN10) -> 0 | T31: =SUMIF('2.Tien do'!$E$7:$AN$7,Summary!T$29,'2.Tien do'!$E10:$AN10) -> 0
D32: Chí phí tiền sử dụng đất | E32: =+E11 -> 21178.41 | F32: =+G32/E32 -> 22.888307 | G32: =+'3.Du toan'!F13 -> 484737.94 | L32: Chi phí tiền sử dụng đất | N32: =SUM(O32:T32) -> 1 | O32: =SUMIF('2.Tien do'!$E$7:$AN$7,Summary!O$29,'2.Tien do'!$E11:$AN11) -> 0 | P32: =SUMIF('2.Tien do'!$E$7:$AN$7,Summary!P$29,'2.Tien do'!$E11:$AN11) -> 1 | Q32: =SUMIF('2.Tien do'!$E$7:$AN$7,Summary!Q$29,'2.Tien do'!$E11:$AN11) -> 0 | R32: =SUMIF('2.Tien do'!$E$7:$AN$7,Summary!R$29,'2.Tien do'!$E11:$AN11) -> 0 | S32: =SUMIF('2.Tien do'!$E$7:$AN$7,Summary!S$29,'2.Tien do'!$E11:$AN11) -> 0 | T32: =SUMIF('2.Tien do'!$E$7:$AN$7,Summary!T$29,'2.Tien do'!$E11:$AN11) -> 0
D33: Chi phí pháp lý | E33: =+E10 -> 26556 | F33: =+G33/E33 -> 3.2109092 | G33: =+'3.Du toan'!F15 -> 85268.906 | L33: Chi phí pháp lý | N33: =SUM(O33:T33) -> 1 | O33: =SUMIF('2.Tien do'!$E$7:$AN$7,Summary!O$29,'2.Tien do'!$E13:$AN13) -> 0.05 | P33: =SUMIF('2.Tien do'!$E$7:$AN$7,Summary!P$29,'2.Tien do'!$E13:$AN13) -> 0.2 | Q33: =SUMIF('2.Tien do'!$E$7:$AN$7,Summary!Q$29,'2.Tien do'!$E13:$AN13) -> 0.2 | R33: =SUMIF('2.Tien do'!$E$7:$AN$7,Summary!R$29,'2.Tien do'!$E13:$AN13) -> 0.1 | S33: =SUMIF('2.Tien do'!$E$7:$AN$7,Summary!S$29,'2.Tien do'!$E13:$AN13) -> 0.45 | T33: =SUMIF('2.Tien do'!$E$7:$AN$7,Summary!T$29,'2.Tien do'!$E13:$AN13) -> 0
C34: II | D34: Chi phí phát triển dự án | E34: =+J11 -> 172561.1 | F34: =+G34/E34 -> 13.942993 | G34: =SUM(G35:H36) -> 2406018.3 | I34: =+G34/$G$45 -> 0.66745359 | L34: Chi phí phát triển dự án | N34: =SUM(O34:T34) -> 0
D35: Chi phí xây dựng hạ tầng cảnh quan | E35: =+'3.Du toan'!D17 -> 28226.456 | F35: =+G35/E35 -> 0 | G35: =+'3.Du toan'!F17 -> 0 | L35: Hạ tầng kỹ thuật | N35: =SUM(O35:T35) -> 1 | O35: =SUMIF('2.Tien do'!$E$7:$AN$7,Summary!O$29,'2.Tien do'!$E16:$AN16) -> 0 | P35: =SUMIF('2.Tien do'!$E$7:$AN$7,Summary!P$29,'2.Tien do'!$E16:$AN16) -> 0 | Q35: =SUMIF('2.Tien do'!$E$7:$AN$7,Summary!Q$29,'2.Tien do'!$E16:$AN16) -> 1 | R35: =SUMIF('2.Tien do'!$E$7:$AN$7,Summary!R$29,'2.Tien do'!$E16:$AN16) -> 0 | S35: =SUMIF('2.Tien do'!$E$7:$AN$7,Summary!S$29,'2.Tien do'!$E16:$AN16) -> 0 | T35: =SUMIF('2.Tien do'!$E$7:$AN$7,Summary!T$29,'2.Tien do'!$E16:$AN16) -> 0
D36: Chi phí xây dựng công trình chính | E36: =+J11 -> 172561.1 | F36: =+G36/E36 -> 13.942993 | G36: =+H37+H43 -> 2406018.3 | L36: Xây dựng công trình chính
D37: Khối cao tầng | E37: =+J12 -> 146585.35 | F37: =+H37/E37 -> 15.0865 | H37: =+'3.Du toan'!F19 -> 2211460 | L37: Khối cao tầng | N37: =SUM(O37:T37) -> 1 | O37: =SUMIF('3.Du toan'!$AU$8:$CG$8,Summary!O$29,'3.Du toan'!$AU19:$CG19)/'3.Du toan'!$F$19 -> 0 | P37: =SUMIF('3.Du toan'!$AU$8:$CG$8,Summary!P$29,'3.Du toan'!$AU19:$CG19)/'3.Du toan'!$F$19 -> 0.022906514 | Q37: =SUMIF('3.Du toan'!$AU$8:$CG$8,Summary!Q$29,'3.Du toan'!$AU19:$CG19)/'3.Du toan'!$F$19 -> 0.31035501 | R37: =SUMIF('3.Du toan'!$AU$8:$CG$8,Summary!R$29,'3.Du toan'!$AU19:$CG19)/'3.Du toan'!$F$19 -> 0.54648858 | S37: =SUMIF('3.Du toan'!$AU$8:$CG$8,Summary!S$29,'3.Du toan'!$AU19:$CG19)/'3.Du toan'!$F$19 -> 0.12024989 | T37: =SUMIF('3.Du toan'!$AU$8:$CG$8,Summary!T$29,'3.Du toan'!$AU19:$CG19)/'3.Du toan'!$F$19 -> 0
D38: Chi phí xây dựng thiết bị | E38: =+J12 -> 146585.35 | F38: =+H38/E38 -> 13 | H38: =+'3.Du toan'!F20 -> 1905609.6 | L38: Khu nhà liên kế | N38: =SUM(O38:T38) -> 1 | O38: =IFERROR(SUMIF('3.Du toan'!$AU$8:$CG$8,Summary!O$29,'3.Du toan'!$AU61:$CG61)/'3.Du toan'!$F$61,0) -> 0 | P38: =IFERROR(SUMIF('3.Du toan'!$AU$8:$CG$8,Summary!P$29,'3.Du toan'!$AU61:$CG61)/'3.Du toan'!$F$61,0) -> 0 | Q38: =IFERROR(SUMIF('3.Du toan'!$AU$8:$CG$8,Summary!Q$29,'3.Du toan'!$AU61:$CG61)/'3.Du toan'!$F$61,0) -> 0.75 | R38: =IFERROR(SUMIF('3.Du toan'!$AU$8:$CG$8,Summary!R$29,'3.Du toan'!$AU61:$CG61)/'3.Du toan'!$F$61,0) -> 0.25 | S38: =IFERROR(SUMIF('3.Du toan'!$AU$8:$CG$8,Summary!S$29,'3.Du toan'!$AU61:$CG61)/'3.Du toan'!$F$61,0) -> 0 | T38: =IFERROR(SUMIF('3.Du toan'!$AU$8:$CG$8,Summary!T$29,'3.Du toan'!$AU61:$CG61)/'3.Du toan'!$F$61,0) -> 0
D39: Chi phí quản lý dự án | F39: =+G39/$E$34 -> 0.11043101 | G39: =+'3.Du toan'!F28 -> 19056.096 | I39: =+'3.Du toan'!E28 -> 0.01
D40: Chi phí tư vấn | F40: =+G40/$E$34 -> 0.44172403 | G40: =+'3.Du toan'!F29 -> 76224.384 | I40: =+'3.Du toan'!E29 -> 0.04
D41: Chi phí khác | F41: =+G41/$E$34 -> 0.055215503 | G41: =+'3.Du toan'!F30 -> 9528.0481 | I41: =+'3.Du toan'!E30 -> 0.005
D42: Chi phí dự phòng cao tầng | F42: =+G42/$E$34 -> 1.1650471 | G42: =+'3.Du toan'!F31 -> 201041.81 | I42: =+'3.Du toan'!E31 -> 0.1
D43: Khối thấp tầng | E43: =+J17 -> 25975.746 | F43: =IFERROR(H43/E43,0) -> 7.49 | H43: =+'3.Du toan'!F61 -> 194558.34
C44: III | D44: Lãi vay vốn hóa (cơ sở ls 12%) | G44: =+'3.Du toan'!F78 -> 108747.29 | I44: =+G44/$G$45 -> 0.030167589
D45: TỔNG CỘNG | G45: =+G30+G34+G44 -> 3604772.4 | I45: =+G45='3.Du toan'!F79 -> TRUE
...

Sheet 1. thong tin quy hoach
B2: =+Summary!B2 -> Dự án Trần Đức 1
B3: Prepared by:
B6: CHỈ TIÊU QUY HOẠCH
B8: STT | C8: Cơ cấu sử dụng đất | D8: Diện tích (m2) | E8: Tỷ lệ (%) | F8: MĐXD (%) | G8: Tầng cao | H8: Diện tích xây dựng (m2) | I8: CFA (m2) | J8: NFA (m2) | K8: NFA - tim tường (m2) | L8: Số sản phẩm | M8: Dân số (người) | N8: Diện tích sản phẩm (đất nền) (m2)
B9: A | C9: Đất khu vực lập quy hoạch (trong ranh) | D9: =D10+D43+D47+D48+D52 -> 26556 | E9: =+D9/D54 -> 0.94081949
B10: 1 | C10: Đất ở | D10: =+D12+D37+D21+D29 -> 21178.41 | E10: =+D10/$D$54 -> 0.75030355 | H10: =+H11+H37 -> 12232.358 | I10: =+I11+I37 -> 172561.1 | J10: =+J11+J37 -> 91551.966 | K10: =+K11+K37 -> 97820.305 | L10: =+L11+L37 -> 1521.3544 | M10: =+M11+M37 -> 2700
B11: 1.1 | C11: Đất chung cư | D11: =+D12+D21+D29 -> 14605.8 | E11: =+D11/$D$54 -> 0.51745072 | G11: =MAX(G12,G21,G29) -> 30 | H11: =+H12+H21+H29 -> 7302.9 | I11: =+I12+I21+I29 -> 146585.35 | J11: =+J12+J21+J29 -> 84979.356 | K11: =+K12+K21+K29 -> 91247.695 | L11: =+L12+L21+L29 -> 1448.3254 | M11: =+M12+M21+M29 -> 2407.884
B12: a | C12: Block A | D12: 15626 | E12: =+D12/$D$54 -> 0.51745072 | F12: 0.386 | G12: 40 | H12: =+D12*F12 -> 7302.9 | I12: =+SUM(I13:I20) -> 146585.35 | J12: =SUM(J13:J20) -> 84979.356 | K12: =SUM(K13:K20) -> 91247.695 | L12: =SUM(L13:L20) -> 1448.3254 | M12: =SUM(M13:M20) -> 2407.884
C13: Căn hộ khối tháp | H13: =+D61*D64 -> 0 | I13: 145652.1 | J13: 106326 | K13: =+J13/O13 -> 81145.098 | L13: 1855 | M13: 3938 | N13: =+K13/L13 -> 63.643214 | O13: 0.93
C14: Căn shop TM khối đế | I14: 13997.7 | J14: 7109.4 | K14: =+J14/O14 -> 2246.1743 | L14: 23 | N14: =+K14/L14 -> 124.78746 | O14: 0.93
C15: OFT | I15: 6282 | J15: 3190.6 | K15: =+J15/O15 -> 6156.4232 | L15: 86 | N15: =+K15/L15 -> 39.892473 | O15: 0.93
C16: Nhà trẻ | I16: 2362.8 | J16: 2008.4 | K16: =+J16 -> 1700 | L16: 1
C17: SHCĐ | I17: 1484
C18: Để xe (tầng nổi)
C19: Để xe + kỹ thuật (hầm) | I19: 31000
C20: Diện tích khác (tum, mái, sân thượng, hồ bơi...) | I20: 1181.4
B21: b | C21: Block B | D21: 0 | E21: =+D21/$D$54 -> 0 | F21: 0.4 | G21: 0 | H21: =+D21*F21 -> 0 | I21: =SUM(I22:I28) -> 0 | J21: =SUM(J22:J28) -> 0 | K21: =SUM(K22:K28) -> 0 | L21: =SUM(L22:L28) -> 0 | M21: =SUM(M22:M28) -> 0
C22: Căn hộ chung cư | H22: =+D66*D69 -> 0 | K22: =+J22/0.93 -> 0 | N22: =+J22/L22 -> #DIV/0!
C23: Căn shop TM | K23: =+J23/0.93 -> 0 | N23: =+J23/L23 -> #DIV/0!
C24: Nhà trẻ | K24: =+J24/0.93 -> 0
C25: SHCĐ
C26: Để xe (tầng nổi)
C27: Để xe + kỹ thuật (hầm)
C28: Diện tích khác (tum, mái, sân thượng, hồ bơi...)
B29: c | C29: Chung cư… | D29: 0 | E29: =+D29/D54 -> 0 | F29: 0.55 | G29: 0 | H29: =+F29*D29 -> 0 | I29: =SUM(I30:I36) -> 0 | J29: =SUM(J30:J36) -> 0 | K29: =SUM(K30:K36) -> 0 | L29: =SUM(L30:L36) -> 0 | M29: =SUM(M30:M36) -> 0
C30: Căn hộ chung cư | H30: =+D71*D74 -> 0 | K30: =+J30/0.93 -> 0 | N30: =+IFERROR(J30/L30,0) -> 0
C31: TMDV | K31: =+J31/0.93 -> 0 | N31: =+IFERROR(J31/L31,0) -> 0
C32: Nhà trẻ | K32: =+J32/0.93 -> 0
C33: SHCĐ
C34: Để xe (tầng nổi)
C35: Nhà xe
C36: Diện tích kỹ thuật khác
B37: 1.2 | C37: Đất nhà ở thấp tầng | D37: =+SUM(D38:D42) -> 6572.61 | E37: =+D37/D54 -> 0.23285282 | F37: =+F38 -> 0.75 | G37: =+G38 -> 3 | H37: =SUM(H38:H42) -> 4929.4575 | I37: =+SUM(I38:I42) -> 25975.746 | J37: =+SUM(J38:J42) -> 6572.61 | K37: =+J37 -> 6572.61 | L37: =+SUM(L38:L42) -> 73.029 | M37: =+SUM(M38:M42) -> 292.116
C38: Nhà ở liên kế khu A | D38: 0 | F38: 0 | G38: 0 | H38: =+D38*F38 -> 4929.4575 | I38: 0 | J38: =+D38 -> 6572.61 | L38: 0 | M38: 0 | N38: =+IFERROR(J38/L38,0) -> 90
C39: Nhà ở liên kế khu B
C40: Shophouse khu C (đường D9)
C41: Biệt thự
B43: 2 | C43: Công trình dịch vụ công cộng | D43: =+SUM(D44:D46) -> 0 | E43: =+D43/$D$54 -> 0 | F43: =+F44 -> 0.4 | H43: =+SUM(H44:H46) -> 0 | I43: =+SUM(I44:I46) -> 0
B44: 2.1 | C44: Trường liên cấp | D44: 0 | F44: 0.4 | G44: 0 | H44: =+D44*F44 -> 0 | I44: =+H44*G44 -> 0
B45: 2.2 | C45: Đất văn hóa | F45: 0.4 | G45: 0 | H45: =+D45*F45 -> 0 | I45: =+H45*G45 -> 0
...

Sheet 2.Tien do
B2: =+Summary!B2 -> Dự án Trần Đức 1
B3: Prepared by:
B5: TIMELINE DỰ ÁN
B7: HẠNG MỤC | D7: CBĐT | E7: 2026 | F7: 2026 | G7: 2026 | H7: 2026 | I7: =H7+1 -> 2027 | J7: =I7 -> 2027 | K7: =J7 -> 2027 | L7: =K7 -> 2027 | M7: =L7+1 -> 2028 | N7: =M7 -> 2028 | O7: =N7 -> 2028 | P7: =L7+1 -> 2028 | Q7: =M7+1 -> 2029 | R7: =N7+1 -> 2029 | S7: =O7+1 -> 2029 | T7: =P7+1 -> 2029 | U7: =Q7+1 -> 2030 | V7: =R7+1 -> 2030 | W7: =S7+1 -> 2030 | ... AN7: =AJ7+1 -> 2034 | AO7: =AN7+1 -> 2035 | AP7: =AO7+1 -> 2036 | AQ7: =AP7+1 -> 2037 | AR7: =AQ7+1 -> 2038
E8: Q1 | F8: Q2 | G8: Q3 | H8: Q4 | I8: Q1 | J8: Q2 | K8: Q3 | L8: Q4 | M8: Q1 | N8: Q2 | O8: Q3 | P8: Q4 | Q8: Q1 | R8: Q2 | S8: Q3 | T8: Q4 | U8: Q1 | V8: Q2 | W8: Q3 | X8: Q4 | Y8: Q1 | Z8: Q2 | AA8: Q3 | AB8: Q4 | AC8: Q1 | AD8: Q2 | AE8: Q3 | AF8: Q4 | AG8: Q1 | AH8: Q2 | AI8: Q3 | AJ8: Q4 | AK8: Q1 | AL8: Q2 | AM8: Q3 | AN8: Q4
B9: GIAI ĐOẠN ĐẦU TƯ & PHÁP LÝ | F9: M&A | G9: Hoàn thành M&A | H9: Chấp thuận CTĐT | I9: QH 1/500 | J9: Đóng LUR | K9: GPXD | N9: Ký HĐMB | O9: Bán thấp tầng | T9: Bàn giao thấp tầng | U9: Bàn giao chung cư | X9: Cấp sổ
C10: Tiến độ giải ngân M&A | F10: 0.3 | G10: 0.7
C11: Chi phí nghĩa vụ tài chính | J11: 1 | M11: 0 | AC11: 0 | AF11: 0 | AG11: 0 | AH11: 0 | AI11: 0 | AJ11: 0 | AK11: 0 | AL11: 0 | AM11: 0 | AN11: 0 | AO11: 0
C12: - | AC12: 0 | AF12: 0 | AG12: 0 | AH12: 0 | AI12: 0 | AJ12: 0 | AK12: 0 | AL12: 0 | AM12: 0 | AN12: 0 | AO12: 0
C13: Pháp lý | H13: 0.05 | I13: 0.05 | J13: 0.05 | K13: 0.1 | N13: 0.2 | Q13: 0.05 | T13: 0.05 | U13: 0.25 | X13: 0.2 | AF13: 0 | AG13: 0 | AH13: 0 | AI13: 0 | AJ13: 0 | AK13: 0 | AL13: 0 | AM13: 0 | AN13: 0 | AO13: 0
B15: HẠNG MỤC XÂY DỰNG
B16: 1 | C16: Hạ tầng kỹ thuật | N16: 0.4 | O16: 0.3 | P16: 0.3 | R16: 0
B17: 2 | C17: Xây dựng công trình chính
B18: 2.1 | C18: Xây dựng Chung cư Sky Habitat
C19: Chuẩn bị thi công | K19: 0.75 | L19: 0.25 | R19: =Q19 -> 0 | V19: =U19 -> 0 | AA19: =Z19 -> 0
C20: Phần ngầm | K20: 0 | L20: 0.05355623 | M20: 0.7 | N20: =1-M20-L20 -> 0.24644377
C21: Phần thân | K21: 0 | L21: 0 | M21: 0 | N21: =100%/8 -> 0.125 | O21: =100%/8 -> 0.125 | P21: =100%/8 -> 0.125 | Q21: =100%/8 -> 0.125 | R21: =100%/8 -> 0.125 | S21: =100%/8 -> 0.125 | T21: =100%/8 -> 0.125 | U21: =100%/8 -> 0.125
C22: Hoàn thiện | K22: 0 | L22: 0 | M22: 0 | N22: 0 | R22: 0.3 | S22: 0.3 | T22: 0.2 | U22: 0.2
C23: M&E | K23: 0 | L23: 0 | M23: 0 | N23: =100%/8 -> 0.125 | O23: =100%/8 -> 0.125 | P23: =100%/8 -> 0.125 | Q23: =100%/8 -> 0.125 | R23: =100%/8 -> 0.125 | S23: =100%/8 -> 0.125 | T23: =100%/8 -> 0.125 | U23: =100%/8 -> 0.125
C24: Xây dựng cảnh quan | K24: 0 | L24: 0 | M24: 0 | N24: 0 | R24: 0.3 | S24: 0.3 | T24: 0.2 | U24: 0.2
C25: Thiết bị | K25: 0 | L25: 0 | M25: 0 | Q25: 0.1 | R25: 0.2 | S25: 0.3 | T25: 0.3 | U25: 0.1
C26: Chi phí quản lý dự án | K26: 0 | L26: =100%/10 -> 0.1 | M26: =100%/10 -> 0.1 | N26: =100%/10 -> 0.1 | O26: =100%/10 -> 0.1 | P26: =100%/10 -> 0.1 | Q26: =100%/10 -> 0.1 | R26: =100%/10 -> 0.1 | S26: =100%/10 -> 0.1 | ... U26: =100%/10 -> 0.1
C27: Chi phí tư vấn đầu tư xây dựng | K27: 0 | L27: =100%/10 -> 0.1 | M27: =100%/10 -> 0.1 | N27: =100%/10 -> 0.1 | O27: =100%/10 -> 0.1 | P27: =100%/10 -> 0.1 | Q27: =100%/10 -> 0.1 | R27: =100%/10 -> 0.1 | S27: =100%/10 -> 0.1 | ... U27: =100%/10 -> 0.1
C28: Chi phí khác | K28: 0 | L28: =100%/10 -> 0.1 | M28: =100%/10 -> 0.1 | N28: =100%/10 -> 0.1 | O28: =100%/10 -> 0.1 | P28: =100%/10 -> 0.1 | Q28: =100%/10 -> 0.1 | R28: =100%/10 -> 0.1 | S28: =100%/10 -> 0.1 | ... U28: =100%/10 -> 0.1
C29: Chi phí dự phòng | K29: 0 | L29: =100%/10 -> 0.1 | M29: =100%/10 -> 0.1 | N29: =100%/10 -> 0.1 | O29: =100%/10 -> 0.1 | P29: =100%/10 -> 0.1 | Q29: =100%/10 -> 0.1 | R29: =100%/10 -> 0.1 | S29: =100%/10 -> 0.1 | ... U29: =100%/10 -> 0.1
B30: 2.2 | C30: Xây dựng Chung cư ….
C31: Chuẩn bị thi công | AA31: =Z31 -> 0
C32: Phần ngầm | G32: 0
C33: Phần thân | G33: 0
C34: Hoàn thiện | G34: 0
C35: M&E | G35: 0
C36: Xây dựng cảnh quan | G36: 0
C37: Thiết bị | G37: 0
C38: Chi phí quản lý dự án | G38: 0
C39: Chi phí tư vấn đầu tư xây dựng | G39: 0
C40: Chi phí khác | G40: 0
C41: Chi phí dự phòng | G41: 0
B42: 2.3 | C42: Xây dựng Chung cư …
C43: Chuẩn bị thi công | AA43: =Z43 -> 0
C44: Phần ngầm | G44: 0 | N44: 0 | O44: 0 | P44: 0 | Q44: 0 | R44: 0 | S44: 0 | T44: 0 | U44: 0 | V44: 0 | W44: 0
...

Sheet 3.Du toan
B2: =+Summary!B2 -> Dự án Trần Đức 1
B3: Prepared by:
B5: DỰ TOÁN ĐẦU TƯ
B7: STT | C7: HẠNG MỤC | D7: SUẤT ĐẦU TƯ | F7: TỔNG (tr.đ) | G7: TIẾN ĐỘ TRIỂN KHAI ĐẦU TƯ XÂY DỰNG | AT7: DÒNG TIỀN CHI TRẢ DỰ TOÁN CHI PHÍ ĐẦU TƯ PHÁT TRIỂN DỰ ÁN
D8: DIỆN TÍCH (m²) | E8: ĐƠN GIÁ (vnd/m²) | G8: CBĐT | H8: ='2.Tien do'!E7 -> 2026 | I8: ='2.Tien do'!F7 -> 2026 | J8: ='2.Tien do'!G7 -> 2026 | K8: ='2.Tien do'!H7 -> 2026 | L8: ='2.Tien do'!I7 -> 2027 | M8: ='2.Tien do'!J7 -> 2027 | N8: ='2.Tien do'!K7 -> 2027 | O8: ='2.Tien do'!L7 -> 2027 | ... AR8: ='2.Tien do'!AO7 -> 2035 | AT8: CBĐT | AU8: ='2.Tien do'!E7 -> 2026 | AV8: ='2.Tien do'!F7 -> 2026 | AW8: ='2.Tien do'!G7 -> 2026 | AX8: ='2.Tien do'!H7 -> 2026 | AY8: ='2.Tien do'!I7 -> 2027 | AZ8: ='2.Tien do'!J7 -> 2027 | BA8: ='2.Tien do'!K7 -> 2027 | BB8: ='2.Tien do'!L7 -> 2027 | ... CG8: ='2.Tien do'!AQ7 -> 2037
H9: ='2.Tien do'!E8 -> Q1 | I9: ='2.Tien do'!F8 -> Q2 | J9: ='2.Tien do'!G8 -> Q3 | K9: ='2.Tien do'!H8 -> Q4 | L9: ='2.Tien do'!I8 -> Q1 | M9: ='2.Tien do'!J8 -> Q2 | N9: ='2.Tien do'!K8 -> Q3 | O9: ='2.Tien do'!L8 -> Q4 | ... AR9: ='2.Tien do'!AO8 -> 0 | AU9: ='2.Tien do'!E8 -> Q1 | AV9: ='2.Tien do'!F8 -> Q2 | AW9: ='2.Tien do'!G8 -> Q3 | AX9: ='2.Tien do'!H8 -> Q4 | AY9: ='2.Tien do'!I8 -> Q1 | AZ9: ='2.Tien do'!J8 -> Q2 | BA9: ='2.Tien do'!K8 -> Q3 | BB9: ='2.Tien do'!L8 -> Q4 | ... CG9: ='2.Tien do'!AQ8 -> 0
B10: CHUẨN BỊ ĐẦU TƯ | D10: ='1. thong tin quy hoach'!$D$59 -> 14605.8 | E10: =F10*10^6/D10 -> 74628356 | F10: =F11+F15 -> 1090006.8 | AT10: =AT11+AT15 -> 0 | AU10: =AU11+AU15 -> 0 | AV10: =AV11+AV15 -> 156000 | AW10: =AW11+AW15 -> 364000 | AX10: =AX11+AX15 -> 4263.4453 | AY10: =AY11+AY15 -> 4263.4453 | AZ10: =AZ11+AZ15 -> 489001.39 | BA10: =BA11+BA15 -> 8526.8906 | ... CE10: =CE11+CE15 -> 0 | CH10: =F10-SUM(AT10:CG10) -> 0
B11: 1 | C11: Chi phí liên quan đến đất | D11: =+'1. thong tin quy hoach'!D54 -> 28226.456 | E11: =F11/D11*10^6 -> 35595611 | F11: =F13+F12+F14 -> 1004737.9 | AT11: =SUM(AT12:AT14) -> 0 | AU11: =SUM(AU12:AU14) -> 0 | AV11: =SUM(AV12:AV14) -> 156000 | AW11: =SUM(AW12:AW14) -> 364000 | AX11: =SUM(AX12:AX14) -> 0 | AY11: =SUM(AY12:AY14) -> 0 | AZ11: =SUM(AZ12:AZ14) -> 484737.94 | BA11: =SUM(BA12:BA14) -> 0 | ... CE11: =SUM(CE12:CE14) -> 0 | CH11: =F11-SUM(AT11:CG11) -> 0
C12: Chi phi mua đất/đấu giá | F12: =+'8.ĐO NHAY'!C20 -> 520000 | H12: ='2.Tien do'!E10 -> 0 | I12: ='2.Tien do'!F10 -> 0.3 | J12: ='2.Tien do'!G10 -> 0.7 | K12: ='2.Tien do'!H10 -> 0 | L12: ='2.Tien do'!I10 -> 0 | M12: ='2.Tien do'!J10 -> 0 | N12: ='2.Tien do'!K10 -> 0 | O12: ='2.Tien do'!L10 -> 0 | ... AR12: ='2.Tien do'!AO10 -> 0 | AT12: =$F12*G12 -> 0 | AU12: =$F12*H12 -> 0 | AV12: =$F12*I12 -> 156000 | AW12: =$F12*J12 -> 364000 | AX12: =$F12*K12 -> 0 | AY12: =$F12*L12 -> 0 | AZ12: =$F12*M12 -> 0 | BA12: =$F12*N12 -> 0 | ... CE12: =$F12*AR12 -> 0 | CH12: =F12-SUM(AT12:CG12) -> 0
C13: Chi phí nghĩa vụ tài chính | F13: =+TSDĐ!G389/10^6 -> 484737.94 | G13: ='2.Tien do'!D11 -> 0 | H13: ='2.Tien do'!E11 -> 0 | I13: ='2.Tien do'!F11 -> 0 | J13: ='2.Tien do'!G11 -> 0 | K13: ='2.Tien do'!H11 -> 0 | L13: ='2.Tien do'!I11 -> 0 | M13: ='2.Tien do'!J11 -> 1 | N13: ='2.Tien do'!K11 -> 0 | ... AR13: ='2.Tien do'!AO11 -> 0 | AT13: =$F13*G13 -> 0 | AU13: =$F13*H13 -> 0 | AV13: =$F13*I13 -> 0 | AW13: =$F13*J13 -> 0 | AX13: =$F13*K13 -> 0 | AY13: =$F13*L13 -> 0 | AZ13: =$F13*M13 -> 484737.94 | BA13: =$F13*N13 -> 0 | ... CE13: =$F13*AR13 -> 0 | CH13: =F13-SUM(AT13:CG13) -> 0
C14: … | F14: 0 | AB14: ='2.Tien do'!Y12 -> 0 | AC14: ='2.Tien do'!Z12 -> 0 | AD14: ='2.Tien do'!AA12 -> 0 | AE14: ='2.Tien do'!AB12 -> 0 | AF14: ='2.Tien do'!AC12 -> 0 | AG14: ='2.Tien do'!AD12 -> 0 | AH14: ='2.Tien do'!AE12 -> 0 | AI14: ='2.Tien do'!AF12 -> 0 | ... AR14: ='2.Tien do'!AO12 -> 0 | AT14: =$F14*G14 -> 0 | AU14: =$F14*H14 -> 0 | AV14: =$F14*I14 -> 0 | AW14: =$F14*J14 -> 0 | AX14: =$F14*K14 -> 0 | AY14: =$F14*L14 -> 0 | AZ14: =$F14*M14 -> 0 | BA14: =$F14*N14 -> 0 | ... CE14: =$F14*AR14 -> 0 | CH14: =F14-SUM(AT14:CG14) -> 0
C15: Pháp lý | D15: =+'1. thong tin quy hoach'!D54 -> 28226.456 | E15: =F15/D15*10^6 -> 3020886 | F15: =2.5%*(F11+F16) -> 85268.906 | G15: ='2.Tien do'!D13 -> 0 | H15: ='2.Tien do'!E13 -> 0 | I15: ='2.Tien do'!F13 -> 0 | J15: ='2.Tien do'!G13 -> 0 | K15: ='2.Tien do'!H13 -> 0.05 | L15: ='2.Tien do'!I13 -> 0.05 | M15: ='2.Tien do'!J13 -> 0.05 | N15: ='2.Tien do'!K13 -> 0.1 | ... AR15: ='2.Tien do'!AO13 -> 0 | AT15: =$F15*G15 -> 0 | AU15: =$F15*H15 -> 0 | AV15: =$F15*I15 -> 0 | AW15: =$F15*J15 -> 0 | AX15: =$F15*K15 -> 4263.4453 | AY15: =$F15*L15 -> 4263.4453 | AZ15: =$F15*M15 -> 4263.4453 | BA15: =$F15*N15 -> 8526.8906 | ... CE15: =$F15*AR15 -> 0 | CH15: =F15-SUM(AT15:CG15) -> 0
A16: =+F16/1.1 -> 2187289.4 | B16: XÂY DỰNG | D16: =+D19+D33 -> 146585.35 | E16: =F16/D16*10^6 -> 16413770 | F16: =F17+F18 -> 2406018.3 | AT16: =+AT17+AT18 -> 0 | AU16: =+AU17+AU18 -> 0 | AV16: =+AV17+AV18 -> 0 | AW16: =+AW17+AW18 -> 0 | AX16: =+AX17+AX18 -> 0 | AY16: =+AY17+AY18 -> 0 | AZ16: =+AZ17+AZ18 -> 0 | BA16: =+BA17+BA18 -> 1429.2072 | ... BR16: =+BR17+BR18 -> 0 | BS16: =+BS19 -> 0 | BT16: =+BT19 -> 0 | BU16: =+BU19 -> 0 | BV16: =+BV19 -> 0 | BW16: =+BW19 -> 0 | BX16: =+BX19 -> 0 | BY16: =+BY19 -> 0 | BZ16: =+BZ19 -> 0 | ... CE16: =+CE19 -> 0 | CH16: =F16-SUM(AT16:CG16) -> 0
A17: =+F17/1.1 -> 0 | B17: 1 | C17: Hạ tầng | D17: =+'1. thong tin quy hoach'!D54 -> 28226.456 | E17: 0 | F17: =+D17*E17/10^6 -> 0 | H17: =+'2.Tien do'!E16 -> 0 | I17: =+'2.Tien do'!F16 -> 0 | J17: =+'2.Tien do'!G16 -> 0 | K17: =+'2.Tien do'!H16 -> 0 | L17: =+'2.Tien do'!I16 -> 0 | M17: =+'2.Tien do'!J16 -> 0 | N17: =+'2.Tien do'!K16 -> 0 | O17: =+'2.Tien do'!L16 -> 0 | ... AR17: =+'2.Tien do'!AO16 -> 0 | AT17: =+G17*$F$17 -> 0 | AU17: =+H17*$F$17 -> 0 | AV17: =+I17*$F$17 -> 0 | AW17: =+J17*$F$17 -> 0 | AX17: =+K17*$F$17 -> 0 | AY17: =+L17*$F$17 -> 0 | AZ17: =+M17*$F$17 -> 0 | BA17: =+N17*$F$17 -> 0 | ... BR17: =+AE17*$F$17 -> 0 | CH17: =F17-SUM(AT17:CG17) -> 0
A18: =+F18/1.1 -> 2187289.4 | B18: 2 | C18: Xây dựng công trình chính | F18: =+F19+F33+F47+F61+F70 -> 2406018.3 | AT18: =+AT19+AT33+AT47+AT61+AT70 -> 0 | AU18: =+AU19+AU33+AU47+AU61+AU70 -> 0 | AV18: =+AV19+AV33+AV47+AV61+AV70 -> 0 | AW18: =+AW19+AW33+AW47+AW61+AW70 -> 0 | AX18: =+AX19+AX33+AX47+AX61+AX70 -> 0 | AY18: =+AY19+AY33+AY47+AY61+AY70 -> 0 | AZ18: =+AZ19+AZ33+AZ47+AZ61+AZ70 -> 0 | BA18: =+BA19+BA33+BA47+BA61+BA70 -> 1429.2072 | ... BR18: =+BR19+BR33+BR47+BR61+BR70 -> 0
B19: 2.1 | C19: =+'2.Tien do'!C18 -> Xây dựng Chung cư Sky Habitat | D19: =+'1. thong tin quy hoach'!I12 -> 146585.35 | E19: =F19/D19*10^6 -> 15086500 | F19: =SUM(F20,F28:F32) -> 2211460 | AT19: =SUM(AT21:AT32) -> 0 | AU19: =SUM(AU21:AU32) -> 0 | AV19: =SUM(AV21:AV32) -> 0 | AW19: =SUM(AW21:AW32) -> 0 | AX19: =SUM(AX21:AX32) -> 0 | AY19: =SUM(AY21:AY32) -> 0 | AZ19: =SUM(AZ21:AZ32) -> 0 | BA19: =SUM(BA21:BA32) -> 1429.2072 | ... CE19: =SUM(CE21:CE32) -> 0 | CH19: =F19-SUM(AT19:CG19) -> 0
C20: Chi phí xây lắp thiết bị | D20: =D19 -> 146585.35 | E20: ='8.ĐO NHAY'!$C$15*10^6 -> 13000000 | F20: =D20*E20/10^6 -> 1905609.6 | AT20: =SUM(AT21:AT27) -> 0 | AU20: =SUM(AU21:AU27) -> 0 | AV20: =SUM(AV21:AV27) -> 0 | AW20: =SUM(AW21:AW27) -> 0 | AX20: =SUM(AX21:AX27) -> 0 | AY20: =SUM(AY21:AY27) -> 0 | AZ20: =SUM(AZ21:AZ27) -> 0 | BA20: =SUM(BA21:BA27) -> 1429.2072 | ... CE20: =SUM(CE21:CE27) -> 0 | CH20: =F20-SUM(AT20:CG20) -> 0
C21: Chuẩn bị thi công | E21: 0.001 | F21: =E21*$F$20 -> 1905.6096 | H21: =+'2.Tien do'!E19 -> 0 | I21: =+'2.Tien do'!F19 -> 0 | J21: =+'2.Tien do'!G19 -> 0 | K21: =+'2.Tien do'!H19 -> 0 | L21: =+'2.Tien do'!I19 -> 0 | M21: =+'2.Tien do'!J19 -> 0 | N21: =+'2.Tien do'!K19 -> 0.75 | O21: =+'2.Tien do'!L19 -> 0.25 | ... AR21: =+'2.Tien do'!AO19 -> 0 | AT21: =$F21*G21 -> 0 | AU21: =$F21*H21 -> 0 | AV21: =$F21*I21 -> 0 | AW21: =$F21*J21 -> 0 | AX21: =$F21*K21 -> 0 | AY21: =$F21*L21 -> 0 | AZ21: =$F21*M21 -> 0 | BA21: =$F21*N21 -> 1429.2072 | ... CE21: =$F21*AR21 -> 0 | CH21: =F21-SUM(AT21:CG21) -> 0
C22: Phần ngầm | E22: 0.178 | F22: =E22*$F$20 -> 339198.51 | H22: =+'2.Tien do'!E20 -> 0 | I22: =+'2.Tien do'!F20 -> 0 | J22: =+'2.Tien do'!G20 -> 0 | K22: =+'2.Tien do'!H20 -> 0 | L22: =+'2.Tien do'!I20 -> 0 | M22: =+'2.Tien do'!J20 -> 0 | N22: =+'2.Tien do'!K20 -> 0 | O22: =+'2.Tien do'!L20 -> 0.05355623 | ... AR22: =+'2.Tien do'!AO20 -> 0 | AT22: =$F22*G22 -> 0 | AU22: =$F22*H22 -> 0 | AV22: =$F22*I22 -> 0 | AW22: =$F22*J22 -> 0 | AX22: =$F22*K22 -> 0 | AY22: =$F22*L22 -> 0 | AZ22: =$F22*M22 -> 0 | BA22: =$F22*N22 -> 0 | ... CE22: =$F22*AR22 -> 0 | CH22: =F22-SUM(AT22:CG22) -> 0
C23: Phần thân | E23: 0.228 | F23: =E23*$F$20 -> 434478.99 | H23: =+'2.Tien do'!E21 -> 0 | I23: =+'2.Tien do'!F21 -> 0 | J23: =+'2.Tien do'!G21 -> 0 | K23: =+'2.Tien do'!H21 -> 0 | L23: =+'2.Tien do'!I21 -> 0 | M23: =+'2.Tien do'!J21 -> 0 | N23: =+'2.Tien do'!K21 -> 0 | O23: =+'2.Tien do'!L21 -> 0 | ... AR23: =+'2.Tien do'!AO21 -> 0 | AT23: =$F23*G23 -> 0 | AU23: =$F23*H23 -> 0 | AV23: =$F23*I23 -> 0 | AW23: =$F23*J23 -> 0 | AX23: =$F23*K23 -> 0 | AY23: =$F23*L23 -> 0 | AZ23: =$F23*M23 -> 0 | BA23: =$F23*N23 -> 0 | ... CE23: =$F23*AR23 -> 0 | CH23: =F23-SUM(AT23:CG23) -> 0
C24: Hoàn thiện | E24: 0.312 | F24: =E24*$F$20 -> 594550.2 | H24: =+'2.Tien do'!E22 -> 0 | I24: =+'2.Tien do'!F22 -> 0 | J24: =+'2.Tien do'!G22 -> 0 | K24: =+'2.Tien do'!H22 -> 0 | L24: =+'2.Tien do'!I22 -> 0 | M24: =+'2.Tien do'!J22 -> 0 | N24: =+'2.Tien do'!K22 -> 0 | O24: =+'2.Tien do'!L22 -> 0 | ... AR24: =+'2.Tien do'!AO22 -> 0 | AT24: =$F24*G24 -> 0 | AU24: =$F24*H24 -> 0 | AV24: =$F24*I24 -> 0 | AW24: =$F24*J24 -> 0 | AX24: =$F24*K24 -> 0 | AY24: =$F24*L24 -> 0 | AZ24: =$F24*M24 -> 0 | BA24: =$F24*N24 -> 0 | ... CE24: =$F24*AR24 -> 0 | CH24: =F24-SUM(AT24:CG24) -> 0
C25: M&E | E25: 0.112 | F25: =E25*$F$20 -> 213428.28 | H25: =+'2.Tien do'!E23 -> 0 | I25: =+'2.Tien do'!F23 -> 0 | J25: =+'2.Tien do'!G23 -> 0 | K25: =+'2.Tien do'!H23 -> 0 | L25: =+'2.Tien do'!I23 -> 0 | M25: =+'2.Tien do'!J23 -> 0 | N25: =+'2.Tien do'!K23 -> 0 | O25: =+'2.Tien do'!L23 -> 0 | ... AR25: =+'2.Tien do'!AO23 -> 0 | AT25: =$F25*G25 -> 0 | AU25: =$F25*H25 -> 0 | AV25: =$F25*I25 -> 0 | AW25: =$F25*J25 -> 0 | AX25: =$F25*K25 -> 0 | AY25: =$F25*L25 -> 0 | AZ25: =$F25*M25 -> 0 | BA25: =$F25*N25 -> 0 | ... CE25: =$F25*AR25 -> 0 | CH25: =F25-SUM(AT25:CG25) -> 0
C26: Xây dựng cảnh quan | E26: 0.017 | F26: =E26*$F$20 -> 32395.363 | H26: =+'2.Tien do'!E24 -> 0 | I26: =+'2.Tien do'!F24 -> 0 | J26: =+'2.Tien do'!G24 -> 0 | K26: =+'2.Tien do'!H24 -> 0 | L26: =+'2.Tien do'!I24 -> 0 | M26: =+'2.Tien do'!J24 -> 0 | N26: =+'2.Tien do'!K24 -> 0 | O26: =+'2.Tien do'!L24 -> 0 | ... AR26: =+'2.Tien do'!AO24 -> 0 | AT26: =$F26*G26 -> 0 | AU26: =$F26*H26 -> 0 | AV26: =$F26*I26 -> 0 | AW26: =$F26*J26 -> 0 | AX26: =$F26*K26 -> 0 | AY26: =$F26*L26 -> 0 | AZ26: =$F26*M26 -> 0 | BA26: =$F26*N26 -> 0 | ... CE26: =$F26*AR26 -> 0 | CH26: =F26-SUM(AT26:CG26) -> 0
C27: Thiết bị | E27: 0.152 | F27: =E27*$F$20 -> 289652.66 | H27: =+'2.Tien do'!E25 -> 0 | I27: =+'2.Tien do'!F25 -> 0 | J27: =+'2.Tien do'!G25 -> 0 | K27: =+'2.Tien do'!H25 -> 0 | L27: =+'2.Tien do'!I25 -> 0 | M27: =+'2.Tien do'!J25 -> 0 | N27: =+'2.Tien do'!K25 -> 0 | O27: =+'2.Tien do'!L25 -> 0 | ... AR27: =+'2.Tien do'!AO25 -> 0 | AT27: =$F27*G27 -> 0 | AU27: =$F27*H27 -> 0 | AV27: =$F27*I27 -> 0 | AW27: =$F27*J27 -> 0 | AX27: =$F27*K27 -> 0 | AY27: =$F27*L27 -> 0 | AZ27: =$F27*M27 -> 0 | BA27: =$F27*N27 -> 0 | ... CE27: =$F27*AR27 -> 0 | CH27: =F27-SUM(AT27:CG27) -> 0
A28: =+F28/1.1 -> 17323.724 | C28: Chi phí quản lý dự án | E28: 0.01 | F28: =E28*$F$20 -> 19056.096 | H28: =+'2.Tien do'!E26 -> 0 | I28: =+'2.Tien do'!F26 -> 0 | J28: =+'2.Tien do'!G26 -> 0 | K28: =+'2.Tien do'!H26 -> 0 | L28: =+'2.Tien do'!I26 -> 0 | M28: =+'2.Tien do'!J26 -> 0 | N28: =+'2.Tien do'!K26 -> 0 | O28: =+'2.Tien do'!L26 -> 0.1 | ... AR28: =+'2.Tien do'!AO26 -> 0 | AT28: =$F28*G28 -> 0 | AU28: =$F28*H28 -> 0 | AV28: =$F28*I28 -> 0 | AW28: =$F28*J28 -> 0 | AX28: =$F28*K28 -> 0 | AY28: =$F28*L28 -> 0 | AZ28: =$F28*M28 -> 0 | BA28: =$F28*N28 -> 0 | ... CE28: =$F28*AR28 -> 0 | CH28: =F28-SUM(AT28:CG28) -> 0
A29: =+F29/1.1 -> 69294.895 | C29: Chi phí tư vấn đầu tư xây dựng | E29: 0.04 | F29: =E29*$F$20 -> 76224.384 | H29: =+'2.Tien do'!E27 -> 0 | I29: =+'2.Tien do'!F27 -> 0 | J29: =+'2.Tien do'!G27 -> 0 | K29: =+'2.Tien do'!H27 -> 0 | L29: =+'2.Tien do'!I27 -> 0 | M29: =+'2.Tien do'!J27 -> 0 | N29: =+'2.Tien do'!K27 -> 0 | O29: =+'2.Tien do'!L27 -> 0.1 | ... AR29: =+'2.Tien do'!AO27 -> 0 | AT29: =$F29*G29 -> 0 | AU29: =$F29*H29 -> 0 | AV29: =$F29*I29 -> 0 | AW29: =$F29*J29 -> 0 | AX29: =$F29*K29 -> 0 | AY29: =$F29*L29 -> 0 | AZ29: =$F29*M29 -> 0 | BA29: =$F29*N29 -> 0 | ... CE29: =$F29*AR29 -> 0 | CH29: =F29-SUM(AT29:CG29) -> 0
A30: =+F30/1.1 -> 8661.8619 | C30: Chi phí khác | E30: 0.005 | F30: =E30*$F$20 -> 9528.0481 | H30: =+'2.Tien do'!E28 -> 0 | I30: =+'2.Tien do'!F28 -> 0 | J30: =+'2.Tien do'!G28 -> 0 | K30: =+'2.Tien do'!H28 -> 0 | L30: =+'2.Tien do'!I28 -> 0 | M30: =+'2.Tien do'!J28 -> 0 | N30: =+'2.Tien do'!K28 -> 0 | O30: =+'2.Tien do'!L28 -> 0.1 | ... AR30: =+'2.Tien do'!AO28 -> 0 | AT30: =$F30*G30 -> 0 | AU30: =$F30*H30 -> 0 | AV30: =$F30*I30 -> 0 | AW30: =$F30*J30 -> 0 | AX30: =$F30*K30 -> 0 | AY30: =$F30*L30 -> 0 | AZ30: =$F30*M30 -> 0 | BA30: =$F30*N30 -> 0 | ... CE30: =$F30*AR30 -> 0 | CH30: =F30-SUM(AT30:CG30) -> 0
A31: =+F31/1.1 -> 182765.29 | C31: Chi phí dự phòng | E31: 0.1 | F31: =E31*(SUM(F28:F30)+F20) -> 201041.81 | H31: =+'2.Tien do'!E29 -> 0 | I31: =+'2.Tien do'!F29 -> 0 | J31: =+'2.Tien do'!G29 -> 0 | K31: =+'2.Tien do'!H29 -> 0 | L31: =+'2.Tien do'!I29 -> 0 | M31: =+'2.Tien do'!J29 -> 0 | N31: =+'2.Tien do'!K29 -> 0 | O31: =+'2.Tien do'!L29 -> 0.1 | ... AR31: =+'2.Tien do'!AO29 -> 0 | AT31: =$F31*G31 -> 0 | AU31: =$F31*H31 -> 0 | AV31: =$F31*I31 -> 0 | AW31: =$F31*J31 -> 0 | AX31: =$F31*K31 -> 0 | AY31: =$F31*L31 -> 0 | AZ31: =$F31*M31 -> 0 | BA31: =$F31*N31 -> 0 | ... CE31: =$F31*AR31 -> 0
E32: 0 | F32: =E32*(SUM(F28:F30)+F20) -> 0 | H32: =+H31 -> 0 | I32: =+I31 -> 0 | J32: =+J31 -> 0 | K32: =+K31 -> 0 | L32: =+L31 -> 0 | S32: =+S31 -> 0.1 | T32: =+T31 -> 0.1 | U32: =+U31 -> 0.1 | V32: =+V31 -> 0.1 | W32: =+W31 -> 0.1 | X32: =+X31 -> 0.1 | Y32: =+Y31 -> 0 | Z32: =+Z31 -> 0 | ... AR32: =+AR31 -> 0 | AT32: =$F32*G32 -> 0 | AU32: =$F32*H32 -> 0 | AV32: =$F32*I32 -> 0 | AW32: =$F32*J32 -> 0 | AX32: =$F32*K32 -> 0 | AY32: =$F32*L32 -> 0 | AZ32: =$F32*M32 -> 0 | BA32: =$F32*N32 -> 0 | ... CE32: =$F32*AR32 -> 0 | CH32: =F32-SUM(AT32:CG32) -> 0
B33: 2.1 | C33: =+'2.Tien do'!C30 -> Xây dựng Chung cư …. | D33: =+'1. thong tin quy hoach'!I21 -> 0 | E33: =F33/D33*10^6 -> #DIV/0! | F33: =SUM(F34,F42:F46) -> 0 | AT33: =SUM(AT35:AT46) -> 0 | AU33: =SUM(AU35:AU46) -> 0 | AV33: =SUM(AV35:AV46) -> 0 | AW33: =SUM(AW35:AW46) -> 0 | AX33: =SUM(AX35:AX46) -> 0 | AY33: =SUM(AY35:AY46) -> 0 | AZ33: =SUM(AZ35:AZ46) -> 0 | BA33: =SUM(BA35:BA46) -> 0 | ... CE33: =SUM(CE35:CE46) -> 0 | CH33: =F33-SUM(AT33:CG33) -> 0
C34: Chi phí xây lắp thiết bị | D34: =D33 -> 0 | E34: ='8.ĐO NHAY'!$C$16*10^6 -> 13000000 | F34: =D34*E34/10^6 -> 0 | AT34: =SUM(AT35:AT41) -> 0 | AU34: =SUM(AU35:AU41) -> 0 | AV34: =SUM(AV35:AV41) -> 0 | AW34: =SUM(AW35:AW41) -> 0 | AX34: =SUM(AX35:AX41) -> 0 | AY34: =SUM(AY35:AY41) -> 0 | AZ34: =SUM(AZ35:AZ41) -> 0 | BA34: =SUM(BA35:BA41) -> 0 | ... CE34: =SUM(CE35:CE41) -> 0 | CH34: =F34-SUM(AT34:CG34) -> 0
C35: Chuẩn bị thi công | E35: 0.001 | F35: =E35*$F$34 -> 0 | H35: =+'2.Tien do'!E31 -> 0 | I35: =+'2.Tien do'!F31 -> 0 | J35: =+'2.Tien do'!G31 -> 0 | K35: =+'2.Tien do'!H31 -> 0 | L35: =+'2.Tien do'!I31 -> 0 | M35: =+'2.Tien do'!J31 -> 0 | N35: =+'2.Tien do'!K31 -> 0 | O35: =+'2.Tien do'!L31 -> 0 | ... AR35: =+'2.Tien do'!AO31 -> 0 | AT35: =$F35*G35 -> 0 | AU35: =$F35*H35 -> 0 | AV35: =$F35*I35 -> 0 | AW35: =$F35*J35 -> 0 | AX35: =$F35*K35 -> 0 | AY35: =$F35*L35 -> 0 | AZ35: =$F35*M35 -> 0 | BA35: =$F35*N35 -> 0 | ... CE35: =$F35*AR35 -> 0 | CH35: =F35-SUM(AT35:CG35) -> 0
C36: Phần ngầm | E36: 0.178 | F36: =E36*$F$34 -> 0 | H36: =+'2.Tien do'!E32 -> 0 | I36: =+'2.Tien do'!F32 -> 0 | J36: =+'2.Tien do'!G32 -> 0 | K36: =+'2.Tien do'!H32 -> 0 | L36: =+'2.Tien do'!I32 -> 0 | M36: =+'2.Tien do'!J32 -> 0 | N36: =+'2.Tien do'!K32 -> 0 | O36: =+'2.Tien do'!L32 -> 0 | ... AR36: =+'2.Tien do'!AO32 -> 0 | AT36: =$F36*G36 -> 0 | AU36: =$F36*H36 -> 0 | AV36: =$F36*I36 -> 0 | AW36: =$F36*J36 -> 0 | AX36: =$F36*K36 -> 0 | AY36: =$F36*L36 -> 0 | AZ36: =$F36*M36 -> 0 | BA36: =$F36*N36 -> 0 | ... CE36: =$F36*AR36 -> 0 | CH36: =F36-SUM(AT36:CG36) -> 0
C37: Phần thân | E37: 0.228 | F37: =E37*$F$34 -> 0 | H37: =+'2.Tien do'!E33 -> 0 | I37: =+'2.Tien do'!F33 -> 0 | J37: =+'2.Tien do'!G33 -> 0 | K37: =+'2.Tien do'!H33 -> 0 | L37: =+'2.Tien do'!I33 -> 0 | M37: =+'2.Tien do'!J33 -> 0 | N37: =+'2.Tien do'!K33 -> 0 | O37: =+'2.Tien do'!L33 -> 0 | ... AR37: =+'2.Tien do'!AO33 -> 0 | AT37: =$F37*G37 -> 0 | AU37: =$F37*H37 -> 0 | AV37: =$F37*I37 -> 0 | AW37: =$F37*J37 -> 0 | AX37: =$F37*K37 -> 0 | AY37: =$F37*L37 -> 0 | AZ37: =$F37*M37 -> 0 | BA37: =$F37*N37 -> 0 | ... CE37: =$F37*AR37 -> 0 | CH37: =F37-SUM(AT37:CG37) -> 0
C38: Hoàn thiện | E38: 0.312 | F38: =E38*$F$34 -> 0 | H38: =+'2.Tien do'!E34 -> 0 | I38: =+'2.Tien do'!F34 -> 0 | J38: =+'2.Tien do'!G34 -> 0 | K38: =+'2.Tien do'!H34 -> 0 | L38: =+'2.Tien do'!I34 -> 0 | M38: =+'2.Tien do'!J34 -> 0 | N38: =+'2.Tien do'!K34 -> 0 | O38: =+'2.Tien do'!L34 -> 0 | ... AR38: =+'2.Tien do'!AO34 -> 0 | AT38: =$F38*G38 -> 0 | AU38: =$F38*H38 -> 0 | AV38: =$F38*I38 -> 0 | AW38: =$F38*J38 -> 0 | AX38: =$F38*K38 -> 0 | AY38: =$F38*L38 -> 0 | AZ38: =$F38*M38 -> 0 | BA38: =$F38*N38 -> 0 | ... CE38: =$F38*AR38 -> 0 | CH38: =F38-SUM(AT38:CG38) -> 0
C39: M&E | E39: 0.112 | F39: =E39*$F$34 -> 0 | H39: =+'2.Tien do'!E35 -> 0 | I39: =+'2.Tien do'!F35 -> 0 | J39: =+'2.Tien do'!G35 -> 0 | K39: =+'2.Tien do'!H35 -> 0 | L39: =+'2.Tien do'!I35 -> 0 | M39: =+'2.Tien do'!J35 -> 0 | N39: =+'2.Tien do'!K35 -> 0 | O39: =+'2.Tien do'!L35 -> 0 | ... AR39: =+'2.Tien do'!AO35 -> 0 | AT39: =$F39*G39 -> 0 | AU39: =$F39*H39 -> 0 | AV39: =$F39*I39 -> 0 | AW39: =$F39*J39 -> 0 | AX39: =$F39*K39 -> 0 | AY39: =$F39*L39 -> 0 | AZ39: =$F39*M39 -> 0 | BA39: =$F39*N39 -> 0 | ... CE39: =$F39*AR39 -> 0 | CH39: =F39-SUM(AT39:CG39) -> 0
C40: Xây dựng cảnh quan | E40: 0.017 | F40: =E40*$F$34 -> 0 | H40: =+'2.Tien do'!E36 -> 0 | I40: =+'2.Tien do'!F36 -> 0 | J40: =+'2.Tien do'!G36 -> 0 | K40: =+'2.Tien do'!H36 -> 0 | L40: =+'2.Tien do'!I36 -> 0 | M40: =+'2.Tien do'!J36 -> 0 | N40: =+'2.Tien do'!K36 -> 0 | O40: =+'2.Tien do'!L36 -> 0 | ... AR40: =+'2.Tien do'!AO36 -> 0 | AT40: =$F40*G40 -> 0 | AU40: =$F40*H40 -> 0 | AV40: =$F40*I40 -> 0 | AW40: =$F40*J40 -> 0 | AX40: =$F40*K40 -> 0 | AY40: =$F40*L40 -> 0 | AZ40: =$F40*M40 -> 0 | BA40: =$F40*N40 -> 0 | ... CE40: =$F40*AR40 -> 0 | CH40: =F40-SUM(AT40:CG40) -> 0
C41: Thiết bị | E41: 0.152 | F41: =E41*$F$34 -> 0 | H41: =+'2.Tien do'!E37 -> 0 | I41: =+'2.Tien do'!F37 -> 0 | J41: =+'2.Tien do'!G37 -> 0 | K41: =+'2.Tien do'!H37 -> 0 | L41: =+'2.Tien do'!I37 -> 0 | M41: =+'2.Tien do'!J37 -> 0 | N41: =+'2.Tien do'!K37 -> 0 | O41: =+'2.Tien do'!L37 -> 0 | ... AR41: =+'2.Tien do'!AO37 -> 0 | AT41: =$F41*G41 -> 0 | AU41: =$F41*H41 -> 0 | AV41: =$F41*I41 -> 0 | AW41: =$F41*J41 -> 0 | AX41: =$F41*K41 -> 0 | AY41: =$F41*L41 -> 0 | AZ41: =$F41*M41 -> 0 | BA41: =$F41*N41 -> 0 | ... CE41: =$F41*AR41 -> 0 | CH41: =F41-SUM(AT41:CG41) -> 0
C42: Chi phí quản lý dự án | E42: 0.01 | F42: =E42*$F$34 -> 0 | H42: =+'2.Tien do'!E38 -> 0 | I42: =+'2.Tien do'!F38 -> 0 | J42: =+'2.Tien do'!G38 -> 0 | K42: =+'2.Tien do'!H38 -> 0 | L42: =+'2.Tien do'!I38 -> 0 | M42: =+'2.Tien do'!J38 -> 0 | N42: =+'2.Tien do'!K38 -> 0 | O42: =+'2.Tien do'!L38 -> 0 | ... AR42: =+'2.Tien do'!AO38 -> 0 | AT42: =$F42*G42 -> 0 | AU42: =$F42*H42 -> 0 | AV42: =$F42*I42 -> 0 | AW42: =$F42*J42 -> 0 | AX42: =$F42*K42 -> 0 | AY42: =$F42*L42 -> 0 | AZ42: =$F42*M42 -> 0 | BA42: =$F42*N42 -> 0 | ... CE42: =$F42*AR42 -> 0 | CH42: =F42-SUM(AT42:CG42) -> 0
C43: Chi phí tư vấn đầu tư xây dựng | E43: 0.04 | F43: =E43*$F$34 -> 0 | H43: =+'2.Tien do'!E39 -> 0 | I43: =+'2.Tien do'!F39 -> 0 | J43: =+'2.Tien do'!G39 -> 0 | K43: =+'2.Tien do'!H39 -> 0 | L43: =+'2.Tien do'!I39 -> 0 | M43: =+'2.Tien do'!J39 -> 0 | N43: =+'2.Tien do'!K39 -> 0 | O43: =+'2.Tien do'!L39 -> 0 | ... AR43: =+'2.Tien do'!AO39 -> 0 | AT43: =$F43*G43 -> 0 | AU43: =$F43*H43 -> 0 | AV43: =$F43*I43 -> 0 | AW43: =$F43*J43 -> 0 | AX43: =$F43*K43 -> 0 | AY43: =$F43*L43 -> 0 | AZ43: =$F43*M43 -> 0 | BA43: =$F43*N43 -> 0 | ... CE43: =$F43*AR43 -> 0 | CH43: =F43-SUM(AT43:CG43) -> 0
...

Sheet 5.Doanh thu
C2: =+Summary!B2 -> Dự án Trần Đức 1
C3: Prepared by:
C5: DOANH THU DỰ KIẾN
B7: STT | C7: Hạng mục | D7: ĐVT | E7: Tổng | F7: PA2: Bỏ khối văn phòng | G7: GIÁ TRỊ | H7: ='2.Tien do'!E7 -> 2026 | I7: ='2.Tien do'!F7 -> 2026 | J7: ='2.Tien do'!G7 -> 2026 | K7: ='2.Tien do'!H7 -> 2026 | L7: ='2.Tien do'!I7 -> 2027 | M7: ='2.Tien do'!J7 -> 2027 | N7: ='2.Tien do'!K7 -> 2027 | O7: ='2.Tien do'!L7 -> 2027 | ... AQ7: ='2.Tien do'!AN7 -> 2034 | AR7: =AQ7+1 -> 2035 | AS7: =AR7+1 -> 2036 | AT7: =AS7+1 -> 2037 | AU7: =AT7+1 -> 2038 | AV7: =AU7+1 -> 2039 | AW7: =AV7+1 -> 2040 | AX7: =AW7+1 -> 2041 | AY7: =AX7+1 -> 2042 | ... CJ7: =CI7+1 -> 2079 | CK7: end
H8: ='2.Tien do'!E8 -> Q1 | I8: ='2.Tien do'!F8 -> Q2 | J8: ='2.Tien do'!G8 -> Q3 | K8: ='2.Tien do'!H8 -> Q4 | L8: ='2.Tien do'!I8 -> Q1 | M8: ='2.Tien do'!J8 -> Q2 | N8: ='2.Tien do'!K8 -> Q3 | O8: ='2.Tien do'!L8 -> Q4 | ... AQ8: ='2.Tien do'!AN8 -> Q4 | CK8: end
H9: 3 | I9: 3 | J9: 3 | K9: 3 | L9: 3 | M9: 3 | N9: 3 | O9: 3 | P9: 3 | Q9: 3 | R9: 3 | S9: 3 | T9: 3 | U9: 3 | V9: 3 | W9: 3 | X9: 3 | Y9: 3 | Z9: 3 | AA9: 3 | AB9: 3 | AC9: 3 | AD9: 3 | AE9: 3 | AF9: 3 | AG9: 3 | AH9: 3 | AI9: 3 | AJ9: 3 | AK9: 3 | AL9: 3 | AM9: 3 | AN9: 3 | AO9: 3 | AP9: 3 | AQ9: 3 | AR9: 12 | AS9: 12 | AT9: 12 | AU9: 12 | AV9: 12 | AW9: 12 | AX9: 12 | AY9: 12 | AZ9: 12 | BA9: 12 | BB9: 12 | BC9: 12 | BD9: 12 | BE9: 12 | BF9: 12 | BG9: 12 | BH9: 12 | BI9: 12 | BJ9: 12 | BK9: 12 | BL9: 12 | BM9: 12 | BN9: 12 | BO9: 12 | BP9: 12 | BQ9: 12 | BR9: 12 | BS9: 12 | BT9: 12 | BU9: 12 | BV9: 12 | BW9: 12 | BX9: 12 | BY9: 12 | BZ9: 12 | CA9: 12 | CB9: 12 | CC9: 12 | CD9: 12 | CE9: 12 | CF9: 12 | CG9: 12 | CH9: 12 | CI9: 12 | CJ9: 12 | CK9: end
B10: 1 | C10: =+'2.Tien do'!C65 -> Căn hộ khối tháp | CK10: end
C11: Tỷ lệ kinh doanh | H11: ='2.Tien do'!E65 -> 0 | I11: ='2.Tien do'!F65 -> 0 | J11: ='2.Tien do'!G65 -> 0 | K11: ='2.Tien do'!H65 -> 0 | L11: ='2.Tien do'!I65 -> 0 | M11: ='2.Tien do'!J65 -> 0 | N11: ='2.Tien do'!K65 -> 0 | O11: ='2.Tien do'!L65 -> 0 | ... CJ11: ='2.Tien do'!CG65 -> 0 | CK11: end
C12: Diện tích bán | D12: m² | E12: =+'1. thong tin quy hoach'!K13 -> 81145.098 | F12: 20610 | G12: =SUM(H12:AA12) -> 81145.098 | H12: =$E12*H11 -> 0 | I12: =$E12*I11 -> 0 | J12: =$E12*J11 -> 0 | K12: =$E12*K11 -> 0 | L12: =$E12*L11 -> 0 | M12: =$E12*M11 -> 0 | N12: =$E12*N11 -> 0 | O12: =$E12*O11 -> 0 | ... CJ12: =$E12*CJ11 -> 0 | CK12: end
C13: Giá bán (gồm VAT) | D13: trđ/m² | E13: =+'8.ĐO NHAY'!C8*(1+'8.ĐO NHAY'!$C$22)-'4.Chi phi hoat dong'!$E$54*('8.ĐO NHAY'!$C$22) -> 51.754461 | F13: 26 | H13: =IF(H12>0,$E13,0) -> 0 | I13: =IF(I12>0,$E13,0) -> 0 | J13: =IF(J12>0,$E13,0) -> 0 | K13: =IF(K12>0,$E13,0) -> 0 | L13: =IF(L12>0,$E13,0) -> 0 | M13: =IF(M12>0,$E13,0) -> 0 | N13: =IF(N12>0,$E13,0) -> 0 | O13: =IF(O12>0,$E13,0) -> 0 | ... CJ13: =IF(CJ12>0,$E13,0) -> 0 | CK13: end
C14: Doanh thu | D14: Tr.đ | E14: =E12*E13 -> 4199620.8 | F14: 535860 | G14: =SUM(H14:DL14) -> 4199620.8 | H14: =H12*H13 -> 0 | I14: =I12*I13 -> 0 | J14: =J12*J13 -> 0 | K14: =K12*K13 -> 0 | L14: =L12*L13 -> 0 | M14: =M12*M13 -> 0 | N14: =N12*N13 -> 0 | O14: =O12*O13 -> 0 | ... CJ14: =CJ12*CJ13 -> 0 | CK14: end
C15: Thực thu | D15: Tr.đ | G15: =SUM(H15:DL15) -> 4199620.8 | H15: 0 | I15: =SUM($H$121:H121)*I14+SUM($H$14:I14)*I121 -> 0 | J15: =SUM($H$121:I121)*J14+SUM($H$14:J14)*J121 -> 0 | K15: =SUM($H$121:J121)*K14+SUM($H$14:K14)*K121 -> 0 | L15: =SUM($H$121:K121)*L14+SUM($H$14:L14)*L121 -> 0 | M15: =SUM($H$121:L121)*M14+SUM($H$14:M14)*M121 -> 0 | N15: =SUM($H$121:M121)*N14+SUM($H$14:N14)*N121 -> 0 | O15: =SUM($H$121:N121)*O14+SUM($H$14:O14)*O121 -> 0 | P15: =SUM($H$121:O121)*P14+SUM($H$14:P14)*P121 -> 0 | ... AQ15: =SUM($H$121:AP121)*AQ14+SUM($H$14:AQ14)*AQ121 -> 0 | CK15: end
B16: 2 | C16: =+'2.Tien do'!C66 -> Căn hộ shop TM | CK16: end
C17: Tỷ lệ kinh doanh | D17: m² | H17: =+'2.Tien do'!E66 -> 0 | I17: =+'2.Tien do'!F66 -> 0 | J17: =+'2.Tien do'!G66 -> 0 | K17: =+'2.Tien do'!H66 -> 0 | L17: =+'2.Tien do'!I66 -> 0 | M17: =+'2.Tien do'!J66 -> 0 | N17: =+'2.Tien do'!K66 -> 0 | O17: =+'2.Tien do'!L66 -> 0 | ... CJ17: =+'2.Tien do'!CG66 -> 0 | CK17: end
C18: Diện tích kinh doanh | D18: trđ/m² | E18: =+'1. thong tin quy hoach'!K14 -> 2246.1743 | F18: 4031.2 | G18: =SUM(H18:AA18) -> 2246.1743 | H18: =$E18*H17 -> 0 | I18: =$E18*I17 -> 0 | J18: =$E18*J17 -> 0 | K18: =$E18*K17 -> 0 | L18: =$E18*L17 -> 0 | M18: =$E18*M17 -> 0 | N18: =$E18*N17 -> 0 | O18: =$E18*O17 -> 0 | ... CJ18: =$E18*CJ17 -> 0 | CK18: end
C19: Giá bán (gồm VAT) | D19: Tr.đ | E19: =+'8.ĐO NHAY'!C9*(1+'8.ĐO NHAY'!$C$22)-'4.Chi phi hoat dong'!$E$54*('8.ĐO NHAY'!$C$22) -> 54.504461 | F19: 60 | H19: =IF(H18>0,$E19,0) -> 0 | I19: =IF(I18>0,$E19,0) -> 0 | J19: =IF(J18>0,$E19,0) -> 0 | K19: =IF(K18>0,$E19,0) -> 0 | L19: =IF(L18>0,$E19,0) -> 0 | M19: =IF(M18>0,$E19,0) -> 0 | N19: =IF(N18>0,$E19,0) -> 0 | O19: =IF(O18>0,$E19,0) -> 0 | ... CJ19: =IF(CJ18>0,$E19,0) -> 0 | CK19: end
C20: Doanh thu | D20: Tr.đ | E20: =G20 -> 122426.52 | F20: 241872 | G20: =SUM(H20:XFD20) -> 122426.52 | H20: =H18*H19 -> 0 | I20: =I18*I19 -> 0 | J20: =J18*J19 -> 0 | K20: =K18*K19 -> 0 | L20: =L18*L19 -> 0 | M20: =M18*M19 -> 0 | N20: =N18*N19 -> 0 | O20: =O18*O19 -> 0 | ... CJ20: =CJ18*CJ19 -> 0 | CK20: end
C21: Thực thu | E21: =(G27+G21)/E18 -> 54.504461 | G21: =SUM(H21:XFD21) -> 122426.52 | H21: 0 | I21: =SUM($H$122:H122)*I20+SUM($H$20:I20)*I122 -> 0 | J21: =SUM($H$122:I122)*J20+SUM($H$20:J20)*J122 -> 0 | K21: =SUM($H$122:J122)*K20+SUM($H$20:K20)*K122 -> 0 | L21: =SUM($H$122:K122)*L20+SUM($H$20:L20)*L122 -> 0 | M21: =SUM($H$122:L122)*M20+SUM($H$20:M20)*M122 -> 0 | N21: =SUM($H$122:M122)*N20+SUM($H$20:N20)*N122 -> 0 | O21: =SUM($H$122:N122)*O20+SUM($H$20:O20)*O122 -> 0 | P21: =SUM($H$122:O122)*P20+SUM($H$20:P20)*P122 -> 0 | ... AQ21: =SUM($H$122:AP122)*AQ20+SUM($H$20:AQ20)*AQ122 -> 0 | CK21: end
B22: 3 | C22: =+'2.Tien do'!C67 -> Căn TMDV | CK22: end
C23: Tỷ lệ kinh doanh | D23: m² | H23: ='2.Tien do'!E67 -> 0 | I23: ='2.Tien do'!F67 -> 0 | J23: ='2.Tien do'!G67 -> 0 | K23: ='2.Tien do'!H67 -> 0 | L23: ='2.Tien do'!I67 -> 0 | M23: ='2.Tien do'!J67 -> 0 | N23: ='2.Tien do'!K67 -> 0 | O23: ='2.Tien do'!L67 -> 0 | ... CJ23: ='2.Tien do'!CG67 -> 0 | CK23: end
C24: Diện tích kinh doanh | D24: trđ/m² | E24: 0 | G24: =SUM(H24:AA24) -> 0 | H24: =$E24*H23 -> 0 | I24: =$E24*I23 -> 0 | J24: =$E24*J23 -> 0 | K24: =$E24*K23 -> 0 | L24: =$E24*L23 -> 0 | M24: =$E24*M23 -> 0 | N24: =$E24*N23 -> 0 | O24: =$E24*O23 -> 0 | ... CJ24: =$E24*CJ23 -> 0 | CK24: end
C25: Giá bán (gồm VAT) | D25: Tr.đ | E25: =+'8.ĐO NHAY'!C10*(1+'8.ĐO NHAY'!$C$22)-'4.Chi phi hoat dong'!$E$54*('8.ĐO NHAY'!$C$22) -> -0.49553918 | H25: =IF(H24>0,$E25,0) -> 0 | I25: =IF(I24>0,$E25,0) -> 0 | J25: =IF(J24>0,$E25,0) -> 0 | K25: =IF(K24>0,$E25,0) -> 0 | L25: =IF(L24>0,$E25,0) -> 0 | M25: =IF(M24>0,$E25,0) -> 0 | N25: =IF(N24>0,$E25,0) -> 0 | O25: =IF(O24>0,$E25,0) -> 0 | ... CJ25: =IF(CJ24>0,$E25,0) -> 0 | CK25: end
C26: Doanh thu | D26: Tr.đ | E26: =+G26 -> 0 | G26: =SUM(H26:XFD26) -> 0 | H26: =H24*H25 -> 0 | I26: =I24*I25 -> 0 | J26: =J24*J25 -> 0 | K26: =K24*K25 -> 0 | L26: =L24*L25 -> 0 | M26: =M24*M25 -> 0 | N26: =N24*N25 -> 0 | O26: =O24*O25 -> 0 | ... CJ26: =CJ24*CJ25 -> 0 | CK26: end
C27: Thực thu | G27: =SUM(H27:XFD27) -> 0 | H27: 0 | I27: =SUM($H$123:H123)*I26+SUM($H$26:I26)*I123 -> 0 | J27: =SUM($H$123:I123)*J26+SUM($H$26:J26)*J123 -> 0 | K27: =SUM($H$123:J123)*K26+SUM($H$26:K26)*K123 -> 0 | L27: =SUM($H$123:K123)*L26+SUM($H$26:L26)*L123 -> 0 | M27: =SUM($H$123:L123)*M26+SUM($H$26:M26)*M123 -> 0 | N27: =SUM($H$123:M123)*N26+SUM($H$26:N26)*N123 -> 0 | O27: =SUM($H$123:N123)*O26+SUM($H$26:O26)*O123 -> 0 | P27: =SUM($H$123:O123)*P26+SUM($H$26:P26)*P123 -> 0 | ... AQ27: =SUM($H$123:AP123)*AQ26+SUM($H$26:AQ26)*AQ123 -> 0 | CK27: end
B28: 4 | C28: =+'2.Tien do'!C68 -> Căn officetel | CK28: end
C29: Tỷ lệ kinh doanh | D29: m² | H29: =+'2.Tien do'!E68 -> 0 | I29: =+'2.Tien do'!F68 -> 0 | J29: =+'2.Tien do'!G68 -> 0 | K29: =+'2.Tien do'!H68 -> 0 | L29: =+'2.Tien do'!I68 -> 0 | M29: =+'2.Tien do'!J68 -> 0 | N29: =+'2.Tien do'!K68 -> 0 | O29: =+'2.Tien do'!L68 -> 0 | ... CJ29: =+'2.Tien do'!CG68 -> 0 | CK29: end
C30: Diện tích kinh doanh | D30: trđ/m² | E30: =+'1. thong tin quy hoach'!K15 -> 6156.4232 | G30: =SUM(H30:AA30) -> 6156.4232 | H30: =$E30*H29 -> 0 | I30: =$E30*I29 -> 0 | J30: =$E30*J29 -> 0 | K30: =$E30*K29 -> 0 | L30: =$E30*L29 -> 0 | M30: =$E30*M29 -> 0 | N30: =$E30*N29 -> 0 | O30: =$E30*O29 -> 0 | ... CJ30: =$E30*CJ29 -> 0 | CK30: end
C31: Giá bán | D31: Tr.đ | E31: =+'8.ĐO NHAY'!C11*(1+'8.ĐO NHAY'!$C$22)-'4.Chi phi hoat dong'!$E$54*('8.ĐO NHAY'!$C$22) -> 49.141961 | H31: =IF(H30>0,$E31,0) -> 0 | I31: =IF(I30>0,$E31,0) -> 0 | J31: =IF(J30>0,$E31,0) -> 0 | K31: =IF(K30>0,$E31,0) -> 0 | L31: =IF(L30>0,$E31,0) -> 0 | M31: =IF(M30>0,$E31,0) -> 0 | N31: =IF(N30>0,$E31,0) -> 0 | O31: =IF(O30>0,$E31,0) -> 0 | ... CJ31: =IF(CJ30>0,$E31,0) -> 0 | CK31: end
C32: Doanh thu | D32: Tr.đ | E32: =+G32 -> 302538.71 | G32: =SUM(H32:XFD32) -> 302538.71 | H32: =H30*H31 -> 0 | I32: =I30*I31 -> 0 | J32: =J30*J31 -> 0 | K32: =K30*K31 -> 0 | L32: =L30*L31 -> 0 | M32: =M30*M31 -> 0 | N32: =N30*N31 -> 0 | O32: =O30*O31 -> 0 | ... CJ32: =CJ30*CJ31 -> 0 | CK32: end
C33: Thực thu | G33: =SUM(H33:XFD33) -> 302538.71 | H33: 0 | I33: =SUM($H$124:H124)*I32+SUM($H$32:I32)*I124 -> 0 | J33: =SUM($H$124:I124)*J32+SUM($H$32:J32)*J124 -> 0 | K33: =SUM($H$124:J124)*K32+SUM($H$32:K32)*K124 -> 0 | L33: =SUM($H$124:K124)*L32+SUM($H$32:L32)*L124 -> 0 | M33: =SUM($H$124:L124)*M32+SUM($H$32:M32)*M124 -> 0 | N33: =SUM($H$124:M124)*N32+SUM($H$32:N32)*N124 -> 0 | O33: =SUM($H$124:N124)*O32+SUM($H$32:O32)*O124 -> 0 | P33: =SUM($H$124:O124)*P32+SUM($H$32:P32)*P124 -> 0 | ... AQ33: =SUM($H$124:AP124)*AQ32+SUM($H$32:AQ32)*AQ124 -> 0 | CK33: end
B34: 5 | C34: 0 | CK34: end
C35: Tỷ lệ kinh doanh | H35: =+'2.Tien do'!E69 -> 0 | I35: =+'2.Tien do'!F69 -> 0 | J35: =+'2.Tien do'!G69 -> 0 | K35: =+'2.Tien do'!H69 -> 0 | L35: =+'2.Tien do'!I69 -> 0 | M35: =+'2.Tien do'!J69 -> 0 | N35: =+'2.Tien do'!K69 -> 0 | O35: =+'2.Tien do'!L69 -> 0 | ... CJ35: =+'2.Tien do'!CG69 -> 0 | CK35: end
C36: Diện tích bán | D36: m² | E36: 0 | F36: 20610 | G36: =SUM(H36:AA36) -> 0 | H36: =$E36*H35 -> 0 | I36: =$E36*I35 -> 0 | J36: =$E36*J35 -> 0 | K36: =$E36*K35 -> 0 | L36: =$E36*L35 -> 0 | M36: =$E36*M35 -> 0 | N36: =$E36*N35 -> 0 | O36: =$E36*O35 -> 0 | ... CJ36: =$E36*CJ35 -> 0 | CK36: end
C37: Giá bán | D37: trđ/m² | E37: =+'8.ĐO NHAY'!C8 -> 47.5 | F37: 26 | H37: =IF(H36>0,$E37,0) -> 0 | I37: =IF(I36>0,$E37,0) -> 0 | J37: =IF(J36>0,$E37,0) -> 0 | K37: =IF(K36>0,$E37,0) -> 0 | L37: =IF(L36>0,$E37,0) -> 0 | M37: =IF(M36>0,$E37,0) -> 0 | N37: =IF(N36>0,$E37,0) -> 0 | O37: =IF(O36>0,$E37,0) -> 0 | ... CJ37: =IF(CJ36>0,$E37,0) -> 0 | CK37: end
C38: Doanh thu | D38: Tr.đ | E38: =E36*E37 -> 0 | F38: 535860 | G38: =SUM(H38:DL38) -> 0 | H38: =H36*H37 -> 0 | I38: =I36*I37 -> 0 | J38: =J36*J37 -> 0 | K38: =K36*K37 -> 0 | L38: =L36*L37 -> 0 | M38: =M36*M37 -> 0 | N38: =N36*N37 -> 0 | O38: =O36*O37 -> 0 | ... CJ38: =CJ36*CJ37 -> 0 | CK38: end
C39: Thực thu | D39: Tr.đ | G39: =SUM(H39:DL39) -> 0 | H39: 0 | I39: =SUM($H$125:H125)*I38+SUM($H$38:I38)*I125 -> 0 | J39: =SUM($H$125:I125)*J38+SUM($H$38:J38)*J125 -> 0 | K39: =SUM($H$125:J125)*K38+SUM($H$38:K38)*K125 -> 0 | L39: =SUM($H$125:K125)*L38+SUM($H$38:L38)*L125 -> 0 | M39: =SUM($H$125:L125)*M38+SUM($H$38:M38)*M125 -> 0 | N39: =SUM($H$125:M125)*N38+SUM($H$38:N38)*N125 -> 0 | O39: =SUM($H$125:N125)*O38+SUM($H$38:O38)*O125 -> 0 | P39: =SUM($H$125:O125)*P38+SUM($H$38:P38)*P125 -> 0 | ... AQ39: =SUM($H$125:AP125)*AQ38+SUM($H$38:AQ38)*AQ125 -> 0 | CK39: end
B40: 6 | C40: 0 | CK40: end
C41: Tỷ lệ kinh doanh | D41: m² | H41: =+'2.Tien do'!E70 -> 0 | I41: =+'2.Tien do'!F70 -> 0 | J41: =+'2.Tien do'!G70 -> 0 | K41: =+'2.Tien do'!H70 -> 0 | L41: =+'2.Tien do'!I70 -> 0 | M41: =+'2.Tien do'!J70 -> 0 | N41: =+'2.Tien do'!K70 -> 0 | O41: =+'2.Tien do'!L70 -> 0 | ... CJ41: =+'2.Tien do'!CG70 -> 0 | CK41: end
C42: Diện tích kinh doanh | D42: trđ/m² | E42: 0 | F42: 4031.2 | G42: =SUM(H42:AA42) -> 0 | H42: =$E42*H41 -> 0 | I42: =$E42*I41 -> 0 | J42: =$E42*J41 -> 0 | K42: =$E42*K41 -> 0 | L42: =$E42*L41 -> 0 | M42: =$E42*M41 -> 0 | N42: =$E42*N41 -> 0 | O42: =$E42*O41 -> 0 | ... CJ42: =$E42*CJ41 -> 0 | CK42: end
C43: Giá bán | D43: Tr.đ | E43: 80 | F43: 60 | H43: =IF(H42>0,$E43,0) -> 0 | I43: =IF(I42>0,$E43,0) -> 0 | J43: =IF(J42>0,$E43,0) -> 0 | K43: =IF(K42>0,$E43,0) -> 0 | L43: =IF(L42>0,$E43,0) -> 0 | M43: =IF(M42>0,$E43,0) -> 0 | N43: =IF(N42>0,$E43,0) -> 0 | O43: =IF(O42>0,$E43,0) -> 0 | ... CJ43: =IF(CJ42>0,$E43,0) -> 0 | CK43: end
...

Sheet 4.Chi phi hoat dong
C2: =+Summary!B2 -> Dự án Trần Đức 1
C3: Prepared by:
B5: A. | C5: CHI PHÍ HOẠT ĐỘNG VÀ THUẾ
B7: STT | C7: KHOẢN MỤC CHI PHÍ | D7: Tỷ lệ %/doanh thu bán hàng | E7: Tổng | F7: CHI PHÍ BÁN HÀNG PHÂN BỔ THEO QUÝ VÀ NĂM
F8: CBĐT | G8: ='5.Doanh thu'!H7 -> 2026 | H8: ='5.Doanh thu'!I7 -> 2026 | I8: ='5.Doanh thu'!J7 -> 2026 | J8: ='5.Doanh thu'!K7 -> 2026 | K8: ='5.Doanh thu'!L7 -> 2027 | L8: ='5.Doanh thu'!M7 -> 2027 | M8: ='5.Doanh thu'!N7 -> 2027 | N8: ='5.Doanh thu'!O7 -> 2027 | ... CI8: ='5.Doanh thu'!CJ7 -> 2079
G9: ='5.Doanh thu'!H8 -> Q1 | H9: ='5.Doanh thu'!I8 -> Q2 | I9: ='5.Doanh thu'!J8 -> Q3 | J9: ='5.Doanh thu'!K8 -> Q4 | K9: ='5.Doanh thu'!L8 -> Q1 | L9: ='5.Doanh thu'!M8 -> Q2 | M9: ='5.Doanh thu'!N8 -> Q3 | N9: ='5.Doanh thu'!O8 -> Q4 | ... AD9: ='5.Doanh thu'!AE8 -> Q4
B10: 1 | C10: Chi phí bán hàng, tiếp thị và DVKH | D10: =+E10/SUM(D33:D36,D39) -> 0.17501772 | E10: =SUM(F10:XFD10) -> 910042.9 | F10: =SUM(F11:F15) -> 0 | G10: =SUM(G11:G17) -> 0 | H10: =SUM(H11:H17) -> 0 | I10: =SUM(I11:I17) -> 0 | J10: =SUM(J11:J17) -> 0 | K10: =SUM(K11:K17) -> 0 | L10: =SUM(L11:L17) -> 0 | M10: =SUM(M11:M17) -> 0 | N10: =SUM(N11:N17) -> 0 | ... CI10: =SUM(CI11:CI17) -> 0
C11: Chi phí Môi Giới (%doanh thu) | D11: 0.07 | E11: =SUM(F11:XFD11) -> 363980.31 | G11: =$D11*SUM(G$33:G$36,G$39) -> 0 | H11: =$D11*SUM(H$33:H$36,H$39) -> 0 | I11: =$D11*SUM(I$33:I$36,I$39) -> 0 | J11: =$D11*SUM(J$33:J$36,J$39) -> 0 | K11: =$D11*SUM(K$33:K$36,K$39) -> 0 | L11: =$D11*SUM(L$33:L$36,L$39) -> 0 | M11: =$D11*SUM(M$33:M$36,M$39) -> 0 | N11: =$D11*SUM(N$33:N$36,N$39) -> 0 | ... CI11: =$D11*SUM(CI$33:CI$36,CI$39) -> 0
C12: Chi phí tiếp thị (%doanh thu) | D12: 0.02 | E12: =SUM(F12:XFD12) -> 103994.37 | G12: =$D12*SUM(G$33:G$36,G$39) -> 0 | H12: =$D12*SUM(H$33:H$36,H$39) -> 0 | I12: =$D12*SUM(I$33:I$36,I$39) -> 0 | J12: =$D12*SUM(J$33:J$36,J$39) -> 0 | K12: =$D12*SUM(K$33:K$36,K$39) -> 0 | L12: =$D12*SUM(L$33:L$36,L$39) -> 0 | M12: =$D12*SUM(M$33:M$36,M$39) -> 0 | N12: =$D12*SUM(N$33:N$36,N$39) -> 0 | ... CI12: =$D12*SUM(CI$33:CI$36,CI$39) -> 0
C13: Chi phí Push Sale (%doanh thu) | D13: 0.067 | E13: =SUM(F13:XFD13) -> 348381.15 | G13: =$D13*SUM(G$33:G$36,G$39) -> 0 | H13: =$D13*SUM(H$33:H$36,H$39) -> 0 | I13: =$D13*SUM(I$33:I$36,I$39) -> 0 | J13: =$D13*SUM(J$33:J$36,J$39) -> 0 | K13: =$D13*SUM(K$33:K$36,K$39) -> 0 | L13: =$D13*SUM(L$33:L$36,L$39) -> 0 | M13: =$D13*SUM(M$33:M$36,M$39) -> 0 | N13: =$D13*SUM(N$33:N$36,N$39) -> 0 | ... CI13: =$D13*SUM(CI$33:CI$36,CI$39) -> 0
C14: Chi phí Nhà mẫu (%doanh thu) | D14: 0.01 | E14: =SUM(F14:XFD14) -> 51997.187 | G14: =$D14*SUM(G$33:G$36,G$39) -> 0 | H14: =$D14*SUM(H$33:H$36,H$39) -> 0 | I14: =$D14*SUM(I$33:I$36,I$39) -> 0 | J14: =$D14*SUM(J$33:J$36,J$39) -> 0 | K14: =$D14*SUM(K$33:K$36,K$39) -> 0 | L14: =$D14*SUM(L$33:L$36,L$39) -> 0 | M14: =$D14*SUM(M$33:M$36,M$39) -> 0 | N14: =$D14*SUM(N$33:N$36,N$39) -> 0 | ... CI14: =$D14*SUM(CI$33:CI$36,CI$39) -> 0
C15: Chi phí dịch vụ khách hàng (%thực thu) | D15: 0.005 | E15: =SUM(F15:XFD15) -> 25998.593 | G15: =$D15*SUM(G$43:G$46,G$49) -> 0 | H15: =$D15*SUM(H$43:H$46,H$49) -> 0 | I15: =$D15*SUM(I$43:I$46,I$49) -> 0 | J15: =$D15*SUM(J$43:J$46,J$49) -> 0 | K15: =$D15*SUM(K$43:K$46,K$49) -> 0 | L15: =$D15*SUM(L$43:L$46,L$49) -> 0 | M15: =$D15*SUM(M$43:M$46,M$49) -> 0 | N15: =$D15*SUM(N$43:N$46,N$49) -> 0 | ... CI15: =$D15*SUM(CI$43:CI$46,CI$49) -> 0
C16: Chi phí hoa hồng kinh doanh tiếp thị (doanh thu) | D16: 0 | E16: =SUM(F16:XFD16) -> 0 | G16: =$D16*SUM(G$33:G$36) -> 0 | H16: =$D16*SUM(H$33:H$36) -> 0 | I16: =$D16*SUM(I$33:I$36) -> 0 | J16: =$D16*SUM(J$33:J$36) -> 0 | K16: =$D16*SUM(K$33:K$36) -> 0 | L16: =$D16*SUM(L$33:L$36) -> 0 | M16: =$D16*SUM(M$33:M$36) -> 0 | N16: =$D16*SUM(N$33:N$36) -> 0 | ... CI16: =$D16*SUM(CI$33:CI$36) -> 0
C17: Chi phí dự phòng bán hàng(doanh thu) | D17: 0.003 | E17: =SUM(F17:XFD17) -> 15691.282 | G17: =$D17*SUM(G$33:G$39) -> 0 | H17: =$D17*SUM(H$33:H$39) -> 0 | I17: =$D17*SUM(I$33:I$39) -> 0 | J17: =$D17*SUM(J$33:J$39) -> 0 | K17: =$D17*SUM(K$33:K$39) -> 0 | L17: =$D17*SUM(L$33:L$39) -> 0 | M17: =$D17*SUM(M$33:M$39) -> 0 | N17: =$D17*SUM(N$33:N$39) -> 0 | ... CI17: =$D17*SUM(CI$33:CI$39) -> 0
B18: 2 | C18: Chi phí Bảo Trì, MG cho TMDV & Nhà tre | D18: 0.05 | E18: =SUM(F18:XFD18) -> 1535.4283 | G18: =$D$18*SUM(G37:G38) -> 0 | H18: =$D$18*SUM(H37:H38) -> 0 | I18: =$D$18*SUM(I37:I38) -> 0 | J18: =$D$18*SUM(J37:J38) -> 0 | K18: =$D$18*SUM(K37:K38) -> 0 | L18: =$D$18*SUM(L37:L38) -> 0 | M18: =$D$18*SUM(M37:M38) -> 0 | N18: =$D$18*SUM(N37:N38) -> 0 | ... CI18: =$D$18*SUM(CI37:CI38) -> 0
B19: 3 | C19: Chi phí lãi vay hỗ trợ khách hàng | E19: =SUM(F19:XFD19) -> 0 | G19: ='6.Vay von'!F23-'3.Du toan'!AU78 -> 0 | H19: ='6.Vay von'!G23-'3.Du toan'!AV78 -> 0 | I19: ='6.Vay von'!H23-'3.Du toan'!AW78 -> 0 | J19: ='6.Vay von'!I23-'3.Du toan'!AX78 -> 0 | K19: ='6.Vay von'!J23-'3.Du toan'!AY78 -> 0 | L19: ='6.Vay von'!K23-'3.Du toan'!AZ78 -> 0 | M19: ='6.Vay von'!L23-'3.Du toan'!BA78 -> 0 | N19: ='6.Vay von'!M23-'3.Du toan'!BB78 -> 0 | ... CI19: ='6.Vay von'!CH23-'3.Du toan'!DW78 -> 0
B20: 4 | C20: Chi phí bảo lãnh ngân hàng | E20: =SUM(F20:XFD20) -> 46994.827 | G20: ='5.Doanh thu'!H72 -> 0 | H20: ='5.Doanh thu'!I72 -> 0 | I20: ='5.Doanh thu'!J72 -> 0 | J20: ='5.Doanh thu'!K72 -> 0 | K20: ='5.Doanh thu'!L72 -> 0 | L20: ='5.Doanh thu'!M72 -> 0 | M20: ='5.Doanh thu'!N72 -> 0 | N20: ='5.Doanh thu'!O72 -> 0 | ... CI20: ='5.Doanh thu'!CJ72 -> 0
B21: 5 | C21: Thuế VAT | E21: =SUM(F21:XFD21) -> 129826.61 | F21: 0 | G21: =IF(SUM($F$22:G22)-SUM($F$21:F21)>0,SUM($F$22:G22)-SUM($F$21:F21),0) -> 0 | H21: =IF(SUM($F$22:H22)-SUM($F$21:G21)>0,SUM($F$22:H22)-SUM($F$21:G21),0) -> 0 | I21: =IF(SUM($F$22:I22)-SUM($F$21:H21)>0,SUM($F$22:I22)-SUM($F$21:H21),0) -> 0 | J21: =IF(SUM($F$22:J22)-SUM($F$21:I21)>0,SUM($F$22:J22)-SUM($F$21:I21),0) -> 0 | K21: =IF(SUM($F$22:K22)-SUM($F$21:J21)>0,SUM($F$22:K22)-SUM($F$21:J21),0) -> 0 | L21: =IF(SUM($F$22:L22)-SUM($F$21:K21)>0,SUM($F$22:L22)-SUM($F$21:K21),0) -> 1.0748574e-12 | M21: =IF(SUM($F$22:M22)-SUM($F$21:L21)>0,SUM($F$22:M22)-SUM($F$21:L21),0) -> 0 | N21: =IF(SUM($F$22:N22)-SUM($F$21:M21)>0,SUM($F$22:N22)-SUM($F$21:M21),0) -> 0 | ... CI21: =IF(SUM($F$22:CI22)-SUM($F$21:CH21)>0,SUM($F$22:CI22)-SUM($F$21:CH21),0) -> 0
C22: Chênh lệch VAT | D22: 0.1 | E22: =SUM(F22:XFD22) -> 129826.61 | F22: =F24-F23 -> 0 | G22: =G24-G23 -> 0 | H22: =H24-H23 -> 0 | I22: =I24-I23 -> 0 | J22: =J24-J23 -> 0 | K22: =K24-K23 -> 0 | L22: =L24-L23 -> 1.0748574e-12 | M22: =M24-M23 -> -129.92793 | ... CI22: =CI24-CI23 -> 0
C23: VAT đầu vào | D23: 0.1 | E23: =SUM(F23:XFD23) -> 301599.69 | F23: =('3.Du toan'!AT77-'3.Du toan'!AT13-'3.Du toan'!AT12+F10+F18)/1.1*0.1 -> 0 | G23: =('3.Du toan'!AU77-'3.Du toan'!AU13-'3.Du toan'!AU12-'3.Du toan'!AU14-'3.Du toan'!AU15+G10+G18)/1.1*0.1 -> 0 | H23: =('3.Du toan'!AV77-'3.Du toan'!AV13-'3.Du toan'!AV12-'3.Du toan'!AV14-'3.Du toan'!AV15+H10+H18)/1.1*0.1 -> 0 | I23: =('3.Du toan'!AW77-'3.Du toan'!AW13-'3.Du toan'!AW12-'3.Du toan'!AW14-'3.Du toan'!AW15+I10+I18)/1.1*0.1 -> 0 | J23: =('3.Du toan'!AX77-'3.Du toan'!AX13-'3.Du toan'!AX12-'3.Du toan'!AX14-'3.Du toan'!AX15+J10+J18)/1.1*0.1 -> 0 | K23: =('3.Du toan'!AY77-'3.Du toan'!AY13-'3.Du toan'!AY12-'3.Du toan'!AY14-'3.Du toan'!AY15+K10+K18)/1.1*0.1 -> 0 | L23: =('3.Du toan'!AZ77-'3.Du toan'!AZ13-'3.Du toan'!AZ12-'3.Du toan'!AZ14-'3.Du toan'!AZ15+L10+L18)/1.1*0.1 -> -1.0748574e-12 | M23: =('3.Du toan'!BA77-'3.Du toan'!BA13-'3.Du toan'!BA12-'3.Du toan'!BA14-'3.Du toan'!BA15+M10+M18)/1.1*0.1 -> 129.92793 | N23: =('3.Du toan'!BB77-'3.Du toan'!BB13-'3.Du toan'!BB12-'3.Du toan'!BB14-'3.Du toan'!BB15+N10+N18)/1.1*0.1 -> 4475.2391 | ... BX23: =('3.Du toan'!DL77-'3.Du toan'!DL13-'3.Du toan'!DL12-'3.Du toan'!DL14-'3.Du toan'!DL15+BX10+BX18)/1.1*0.1 -> 0 | BY23: =('3.Du toan'!DM77-'3.Du toan'!DM11+BY10+BY16++BY18)/1.1*0.1 -> 0 | BZ23: =('3.Du toan'!DN77-'3.Du toan'!DN13-'3.Du toan'!DN12-'3.Du toan'!DN14-'3.Du toan'!DN15+BZ10+BZ18)/1.1*0.1 -> 0 | CA23: =('3.Du toan'!DO77-'3.Du toan'!DO13-'3.Du toan'!DO12-'3.Du toan'!DO14-'3.Du toan'!DO15+CA10+CA18)/1.1*0.1 -> 0 | CB23: =('3.Du toan'!DP77-'3.Du toan'!DP13-'3.Du toan'!DP12-'3.Du toan'!DP14-'3.Du toan'!DP15+CB10+CB18)/1.1*0.1 -> 0 | CC23: =('3.Du toan'!DQ77-'3.Du toan'!DQ13-'3.Du toan'!DQ12-'3.Du toan'!DQ14-'3.Du toan'!DQ15+CC10+CC18)/1.1*0.1 -> 0 | CD23: =('3.Du toan'!DR77-'3.Du toan'!DR13-'3.Du toan'!DR12-'3.Du toan'!DR14-'3.Du toan'!DR15+CD10+CD18)/1.1*0.1 -> 0 | CE23: =('3.Du toan'!DS77-'3.Du toan'!DS13-'3.Du toan'!DS12-'3.Du toan'!DS14-'3.Du toan'!DS15+CE10+CE18)/1.1*0.1 -> 0 | CF23: =('3.Du toan'!DT77-'3.Du toan'!DT13-'3.Du toan'!DT12-'3.Du toan'!DT14-'3.Du toan'!DT15+CF10+CF18)/1.1*0.1 -> 0 | CG23: =('3.Du toan'!DU77-'3.Du toan'!DU13-'3.Du toan'!DU12-'3.Du toan'!DU14-'3.Du toan'!DU15+CG10+CG18)/1.1*0.1 -> 0 | ... CI23: =('3.Du toan'!DW77-'3.Du toan'!DW13-'3.Du toan'!DW12-'3.Du toan'!DW14-'3.Du toan'!DW15+CI10+CI18)/1.1*0.1 -> 0
C24: VAT đầu ra | E24: =SUM(F24:XFD24) -> 431426.3 | F24: =F66 -> 0 | G24: =G66 -> 0 | H24: =H66 -> 0 | I24: =I66 -> 0 | J24: =J66 -> 0 | K24: =K66 -> 0 | L24: =L66 -> 0 | M24: =M66 -> 0 | ... CI24: =CI66 -> 0
